Workbook
Name RentangBernama1: 'KELURAHAN (DI ISI)'!$H:$H

Sheet KELURAHAN (DI ISI)
A1: p
A2: NO | B2: KECAMATAN | C2: ID KEC DAN KELUR | D2: PUSKESMAS | E2: KELURAHAN | F2: Jml Posyd | G2: Balita yang ada
JB3: KENDALI 0-59 BULAN
H4: Januari | P4: Februari | X4: Maret | AF4: April | AN4: Mei | AV4: JUNI | BQ4: JULI | CL4: AGUSTUS | DH4: 33 | EI4: OKTOBER | FJ4: NOVEMBER | GM4: DESEMBER | HT4: KENDALI | JO4: KENDALI DATA DARI FEB-DES | KB4: SELISIH
H5: Total Balita Stunting | I5: Jumlah Balita Stunting Kelompok Umur | M5: Stunting Kasus Baru | N5: Lulus Stunting | O5: Stunting Kasus Lama | P5: Total Balita Stunting | Q5: Jumlah Balita Stunting Kelompok Umur | U5: Stunting Kasus Baru | V5: Lulus Stunting | W5: Stunting Kasus Lama | Y5: Jumlah Balita Stunting Kelompok Umur | AC5: Stunting Kasus Baru | AD5: Lulus Stunting | AE5: Stunting Kasus Lama | AG5: Jumlah Balita Stunting Kelompok Umur | AK5: Stunting Kasus Baru | AL5: Lulus Stunting | AM5: Stunting Kasus Lama | AO5: Jumlah Balita Stunting Kelompok Umur | AS5: Stunting Kasus Baru | AT5: Lulus Stunting | AU5: Stunting Kasus Lama | AV5: Jumlah Balita JUNI 2022 | AW5: Total Balita Stunting | AX5: Jumlah Balita Stunting Kasus Lama | BB5: Jumlah Balita Stunting Baru | BF5: Jumlah Balita Lulus Stunting Membaik | BJ5: Jumlah Balita Lulus ( Pindah ) | BN5: Jumlah Balita Lulus Umur | BO5: Stunting Meninggal | BP5: Jumlah Balita Lulus Stunting | BQ5: Jumlah Balita JULI 2022 | BR5: Total Balita Stunting | BS5: Jumlah Balita Stunting Kasus Lama | BW5: Jumlah Balita Stunting Baru | CA5: Jumlah Balita Lulus Stunting Membaik | CE5: Jumlah Balita Lulus ( Pindah ) | CI5: Jumlah Balita Lulus Umur | CJ5: Stunting Meninggal | CK5: Jumlah Balita Lulus Stunting | CL5: Jumlah Balita AGUSTUS 2022 | CM5: Jumlah Baduta Agustus 2022 | CN5: Total Balita Stunting | CO5: Jumlah Balita Stunting Kasus Lama | CS5: Jumlah Balita Stunting Baru | CW5: Jumlah Balita Lulus Stunting Membaik | DA5: Jumlah Balita Lulus ( Pindah ) | DE5: Jumlah Balita Lulus Umur | DF5: Stunting Meninggal | DG5: Jumlah Balita Lulus Stunting | DH5: Jumlah Balita (S) OKTOBER 2022 | DI5: Jumlah Baduta (S) SEPTEMBER 2022 | DJ5: Balita Ditimbang (D) SEPTEMBER 2022 | DK5: Baduta Ditimbang (D) SEPTEMBER 2022 | DL5: Total Balita Stunting | DM5: Total 0-23 Stunting | DN5: Total 24-59 Stunting | DO5: Jumlah Balita Stunting Kasus Lama | DS5: Jumlah Balita Stunting Baru | DW5: Jumlah Balita Lulus Stunting Membaik | EA5: Jumlah Balita Lulus ( Pindah ) | EE5: Jumlah Balita Lulus Umur | EF5: Stunting Meninggal | EG5: Jumlah Balita Lulus Stunting | EH5: Jumlah Baduta Lulus Stunting | EI5: Jumlah Balita (S) OKTOBER 2022 | EJ5: Jumlah Baduta (S) OKTOBER 2022 | EK5: Balita Ditimbang (D) OKTOBER 2022 | EL5: Baduta Ditimbang (D) OKTOBER 2022 | EM5: Total Balita Stunting | EN5: Total 0-23 Stunting | EO5: Total 24-59 Stunting | EP5: Jumlah Balita Stunting Kasus Lama | ET5: Jumlah Balita Stunting Baru | EX5: Jumlah Balita Lulus Stunting Membaik | FB5: Jumlah Balita Lulus ( Pindah ) | FF5: Jumlah Balita Lulus Umur | FG5: Stunting Meninggal | FH5: Jumlah Balita Lulus Stunting | FI5: Jumlah Baduta Lulus Stunting | FJ5: Jumlah Balita (S) NOVEMBER 2022 | FK5: Jumlah Baduta (S) NOVEMBER 2022 | FL5: Balita Ditimbang (D) NOVEMBER 2022 | FM5: Baduta Ditimbang (D) NOVEMBER 2022 | FN5: Kendali Ditimbang (EPPGBM) KOLOM KOSONG | FO5: KENDALI STUNTING EPPGBM | FP5: Total Balita Stunting | FQ5: Total 0-23 Stunting | FR5: Total 24-59 Stunting | FS5: Jumlah Balita Stunting Kasus Lama | FW5: Jumlah Balita Stunting Baru | GA5: Jumlah Balita Lulus Stunting Membaik | GE5: Jumlah Balita Lulus ( Pindah ) | GI5: Jumlah Balita Lulus Umur | GJ5: Stunting Meninggal | GK5: Jumlah Balita Lulus Stunting | GL5: Jumlah Baduta Lulus Stunting | GM5: Jumlah Balita (S) DESEMBER 2022 | GN5: Jumlah Baduta (S) DESEMBER 2022 | GO5: Balita Ditimbang (D) DESEMBER 2022 | GP5: Baduta Ditimbang (D) DESEMBER 2022 | GQ5: Kendali Ditimbang (EPPGBM) KOLOM KOSONG | GR5: KENDALI STUNTING EPPGBM | GS5: KENDALI STUNTING BADUTA EPPGBM | GT5: Total Balita Stunting | GU5: Total 0-23 Stunting | GV5: Total 24-59 Stunting | GW5: Jumlah Balita Stunting Kasus Lama | HA5: Jumlah Balita Stunting Baru | HE5: Jumlah Balita Lulus Stunting Membaik | HI5: Jumlah Balita Lulus ( Pindah ) | HM5: Jumlah Balita Lulus Umur | HN5: Stunting Meninggal | HO5: Jumlah Balita Lulus Stunting | HP5: Jumlah Baduta Lulus Stunting | HT5: JAN | HU5: FEB | HV5: MAR | HW5: APR | HX5: MEI | HY5: JUNI | HZ5: JULI | IA5: AGT | IB5: SEPT | IC5: OKT | ID5: NOV | IE5: DES | JB5: JAN | JC5: FEB | JD5: MAR | JE5: APR | JF5: MEI | JG5: JUNI | JH5: JULI | JI5: AGT | JJ5: SEPT | JK5: OKT | JL5: NOV | JM5: DES | JO5: JAN | JP5: FEB | JQ5: MAR | JR5: APR | JS5: MEI | JT5: JUNI | JU5: JULI | JV5: AGT | JW5: SEPT | JX5: OKT | JY5: NOV | JZ5: DES | KB5: JAN | KC5: FEB | KD5: MAR | KE5: APR | KF5: MEI | KG5: JUNI | KH5: JULI | KI5: AGT | KJ5: SEPT | KK5: OKT | KL5: NOV | KM5: DES
I6: 0-6 | J6: 6-11 | K6: 12-23 | L6: 24-59 | Q6: 0-6 | R6: 6-11 | S6: 12-23 | T6: 24-59 | X6: Total Balita Stunting | Y6: 0-6 | Z6: 6-11 | AA6: 12-23 | AB6: 24-59 | AF6: Total Balita Stunting | AG6: 0-6 | AH6: 6-11 | AI6: 12-23 | AJ6: 24-59 | AN6: Total Balita Stunting | AO6: 0-6 | AP6: 6-11 | AQ6: 12-23 | AR6: 24-59 | AX6: 0-6 | AY6: 6-11 | AZ6: 12-23 | BA6: 24-59 | BB6: 0-6 | BC6: 6-11 | BD6: 12-23 | BE6: 24-59 | BF6: 0-6 | BG6: 6-11 | BH6: 12-23 | BI6: 24-59 | BJ6: 0-6 | BK6: 6-11 | BL6: 12-23 | BM6: 24-59 | BN6: > 59 | BO6: 0-59 | BP6: 0-59 | BS6: 0-6 | BT6: 6-11 | BU6: 12-23 | BV6: 24-59 | BW6: 0-6 | BX6: 6-11 | BY6: 12-23 | BZ6: 24-59 | CA6: 0-6 | CB6: 6-11 | CC6: 12-23 | CD6: 24-59 | CE6: 0-6 | CF6: 6-11 | CG6: 12-23 | CH6: 24-59 | CI6: > 59 | CJ6: 0-59 | CK6: 0-59 | CO6: 0-6 | CP6: 6-11 | CQ6: 12-23 | CR6: 24-59 | CS6: 0-6 | CT6: 6-11 | CU6: 12-23 | CV6: 24-59 | CW6: 0-6 | CX6: 6-11 | CY6: 12-23 | CZ6: 24-59 | DA6: 0-6 | DB6: 6-11 | DC6: 12-23 | DD6: 24-59 | DE6: > 59 | DF6: 0-59 | DG6: 0-59 | DO6: 0-6 | DP6: 6-11 | DQ6: 12-23 | DR6: 24-59 | DS6: 0-6 | DT6: 6-11 | DU6: 12-23 | DV6: 24-59 | DW6: 0-6 | DX6: 6-11 | DY6: 12-23 | DZ6: 24-59 | EA6: 0-6 | EB6: 6-11 | EC6: 12-23 | ED6: 24-59 | EE6: > 59 | EF6: 0-59 | EP6: 0-6 | EQ6: 6-11 | ER6: 12-23 | ES6: 24-59 | ET6: 0-6 | EU6: 6-11 | EV6: 12-23 | EW6: 24-59 | EX6: 0-6 | EY6: 6-11 | EZ6: 12-23 | FA6: 24-59 | FB6: 0-6 | FC6: 6-11 | FD6: 12-23 | FE6: 24-59 | FF6: > 59 | FG6: 0-59 | FS6: 0-6 | FT6: 6-11 | FU6: 12-23 | FV6: 24-59 | FW6: 0-6 | FX6: 6-11 | FY6: 12-23 | FZ6: 24-59 | GA6: 0-6 | GB6: 6-11 | GC6: 12-23 | GD6: 24-59 | GE6: 0-6 | GF6: 6-11 | GG6: 12-23 | GH6: 24-59 | GI6: > 59 | GJ6: 0-59 | GW6: 0-6 | GX6: 6-11 | GY6: 12-23 | GZ6: 24-59 | HA6: 0-6 | HB6: 6-11 | HC6: 12-23 | HD6: 24-59 | HE6: 0-6 | HF6: 6-11 | HG6: 12-23 | HH6: 24-59 | HI6: 0-6 | HJ6: 6-11 | HK6: 12-23 | HL6: 24-59 | HM6: > 59 | HN6: 0-59
A7: 1 | B7: 2 | D7: 3 | E7: 4 | F7: 5 | G7: 6 | H7: 7 | I7: 8 | J7: 9 | K7: 10 | L7: 11 | M7: 12 | N7: 13 | O7: 14 | P7: 15 | Q7: 16 | R7: 17 | S7: 18 | T7: 19 | U7: 20 | V7: 21 | W7: 22 | X7: 23 | Y7: 24 | Z7: 25 | AA7: 26 | AB7: 27 | AC7: 28 | AD7: 29 | AE7: 30 | AF7: 31 | AG7: 32 | AH7: 33 | AI7: 34 | AJ7: 35 | AK7: 36 | AL7: 37 | AM7: 38 | AN7: 39 | AO7: 40 | AP7: 41 | AQ7: 42 | AR7: 43 | AS7: 44 | AT7: 45 | AU7: 46 | AV7: 47 | AW7: 48 | AX7: 49 | AY7: 50 | AZ7: 51 | BA7: 52 | BB7: 53 | BC7: 54 | BD7: 55 | BE7: 56 | BF7: 57 | BG7: 58 | BH7: 59 | BI7: 60 | BJ7: 61 | BK7: 62 | BL7: 63 | BM7: 64 | BN7: 65 | BO7: 66 | BP7: 67 | BQ7: 68 | BR7: 69 | BS7: 70 | BT7: 71 | BU7: 72 | BV7: 73 | BW7: 74 | BX7: 75 | BY7: 76 | BZ7: 77 | CA7: 78 | CB7: 79 | CC7: 80 | CD7: 81 | CE7: 82 | CF7: 83 | CG7: 84 | CH7: 85 | CI7: 86 | CJ7: 87 | CK7: 88 | CL7: 89 | CM7: 90 | CN7: 91 | CO7: 92 | CP7: 93 | CQ7: 94 | CR7: 95 | CS7: 96 | CT7: 97 | CU7: 98 | CV7: 99 | CW7: 100 | CX7: 101 | CY7: 102 | CZ7: 103 | DA7: 104 | DB7: 105 | DC7: 106 | DD7: 107 | DE7: 108 | DF7: 109 | DG7: 110 | DH7: 111 | DI7: 112 | DJ7: 113 | DK7: 114 | DL7: 115 | DM7: 116 | DO7: 117 | DP7: 118 | DQ7: 119 | DR7: 120 | DS7: 121 | DT7: 122 | DU7: 123 | DV7: 124 | DW7: 125 | DX7: 126 | DY7: 127 | DZ7: 128 | EA7: 129 | EB7: 130 | EC7: 131 | ED7: 132 | EE7: 133 | EF7: 134 | EG7: 135 | EH7: 136 | EI7: 137 | EJ7: 138 | EK7: 139 | EL7: 140 | EM7: 141 | EN7: 142 | EO7: 143 | EP7: 144 | EQ7: 145 | ER7: 146 | ES7: 147 | ET7: 148 | EU7: 149 | EV7: 150 | EW7: 151 | EX7: 152 | EY7: 153 | EZ7: 154 | FA7: 155 | FB7: 156 | FC7: 157 | FD7: 158 | FE7: 159 | FF7: 160 | FG7: 161 | FH7: 162 | FI7: 163 | FJ7: 164 | FK7: 165 | FL7: 166 | FM7: 167 | FP7: 168 | FQ7: 169 | FR7: 170 | FS7: 171 | FT7: 172 | FU7: 173 | FV7: 174 | FW7: 175 | FX7: 176 | FY7: 177 | FZ7: 178 | GA7: 179 | GB7: 180 | GC7: 181 | GD7: 182 | GE7: 183 | GF7: 184 | GG7: 185 | GH7: 186 | GI7: 187 | GJ7: 188 | GK7: 189 | GL7: 190 | GM7: 191 | GN7: 192 | GO7: 193 | GP7: 194 | GQ7: 195 | GR7: 196 | GT7: 197 | GU7: 198 | GV7: 199 | GW7: 200 | GX7: 201 | GY7: 202 | GZ7: 203 | HA7: 204 | HB7: 205 | HC7: 206 | HD7: 207 | HE7: 208 | HF7: 209 | HG7: 210 | HH7: 211 | HI7: 212 | HJ7: 213 | HK7: 214 | HL7: 215 | HM7: 216 | HN7: 217 | HO7: 218 | HP7: 219
A8: 1 | B8: SEMARANG TENGAH | C8: 3374130 | D8: MIROTO | E8: Miroto | F8: 4 | G8: 234 | H8: 1 | L8: 1 | M8: 0 | N8: 0 | O8: =H8-(M8+N8) -> 1 | P8: 1 | S8: 1 | T8: 0 | U8: 1 | V8: 0 | W8: =P8-(U8+V8) -> 0 | X8: 1 | AA8: 1 | AC8: 0 | AD8: 0 | AE8: =X8-(AC8+AD8) -> 1 | AF8: 1 | AI8: 1 | AK8: 0 | AL8: 0 | AM8: =AF8-(AK8+AL8) -> 1 | AN8: 1 | AQ8: 1 | AS8: 0 | AT8: 0 | AU8: =AN8-(AS8+AT8) -> 1 | AV8: 172 | AW8: =SUM(AX8:BE8) -> 2 | AX8: 0 | AY8: 0 | AZ8: 1 | BA8: 0 | BB8: 0 | BC8: 0 | BD8: 1 | BE8: 0 | BF8: 0 | BG8: 0 | BH8: 0 | BI8: 0 | BJ8: 0 | BK8: 0 | BL8: 0 | BM8: 0 | BN8: 0 | BO8: 0 | BP8: =SUM(BF8:BO8) -> 0 | BQ8: 172 | BR8: =SUM(BS8:BZ8) -> 2 | BS8: 0 | BT8: 0 | BU8: 1 | BV8: 1 | BW8: 0 | BX8: 0 | BY8: 0 | BZ8: 0 | CA8: 0 | CB8: 0 | CC8: 0 | CD8: 0 | CE8: 0 | CF8: 0 | CG8: 0 | CH8: 0 | CI8: 0 | CJ8: 0 | CK8: =SUM(CA8:CJ8) -> 0 | CL8: 172 | CM8: 58 | CN8: =SUM(CO8:CV8) -> 2 | CO8: 0 | CP8: 0 | CQ8: 1 | CR8: 1 | CS8: 0 | CT8: 0 | CU8: 0 | CV8: 0 | CW8: 0 | CX8: 0 | CY8: 0 | CZ8: 0 | DA8: 0 | DB8: 0 | DC8: 0 | DD8: 0 | DE8: 0 | DF8: 0 | DG8: =SUM(CW8:DF8) -> 0 | DH8: 116 | DI8: 39 | DJ8: 116 | DK8: 39 | DL8: =SUM(DO8:DV8) -> 2 | DM8: =(DO8+DP8+DQ8+DS8+DT8+DU8) -> 1 | DN8: =DR8+DV8 -> 1 | DO8: 0 | DP8: 0 | DQ8: 1 | DR8: 1 | DS8: 0 | DT8: 0 | DU8: 0 | DV8: 0 | DW8: 0 | DX8: 1 | DY8: 0 | DZ8: 0 | EA8: 0 | EB8: 0 | EC8: 0 | ED8: 0 | EE8: 0 | EF8: 0 | EG8: =SUM(DW8:EF8) -> 1 | EH8: =DW8+DX8+DY8+EA8+EB8+EC8+EE8+EF8 -> 1 | EI8: 116 | EJ8: 39 | EK8: 116 | EL8: 39 | EM8: =SUM(EP8:EW8) -> 2 | EN8: =(EP8+EQ8+ER8+ET8+EU8+EV8) -> 1 | EO8: =ES8+EW8 -> 1 | EP8: 0 | EQ8: 0 | ER8: 1 | ES8: 1 | ET8: 0 | EU8: 0 | EV8: 0 | EW8: 0 | EX8: 0 | EY8: 0 | EZ8: 0 | FA8: 0 | FB8: 0 | FC8: 0 | FD8: 0 | FE8: 0 | FF8: 0 | FG8: 0 | FH8: =SUM(EX8:FG8) -> 0 | FI8: =EX8+EY8+EZ8+FB8+FC8+FD8 -> 0 | FJ8: 110 | FK8: 36 | FL8: 110 | FM8: 36 | FO8: 2 | FP8: =SUM(FS8:FZ8) -> 2 | FQ8: 0 | FR8: 2 | FS8: 0 | FT8: 0 | FU8: 0 | FV8: 2 | FW8: 0 | FX8: 0 | FY8: 0 | FZ8: 0 | GA8: 0 | GB8: 0 | GC8: 0 | GD8: 0 | GE8: 0 | GF8: 0 | GG8: 0 | GH8: 0 | GI8: 0 | GJ8: 0 | GK8: 0 | GL8: 0 | GM8: 109 | GN8: 36 | GO8: 109 | GP8: 36 | GR8: 2 | GS8: 0 | GT8: =GU8+GV8 -> 2 | GU8: =GW8+GX8+GY8+HA8+HB8+HC8 -> 0 | GV8: =GZ8+HD8 -> 2 | GW8: 0 | GX8: 0 | GY8: 0 | GZ8: 2 | HA8: 0 | HB8: 0 | HC8: 0 | HD8: 0 | HE8: 0 | HF8: 0 | HG8: 0 | HH8: 0 | HI8: 0 | HJ8: 0 | HK8: 0 | HL8: 0 | HM8: 0 | HN8: 0 | HO8: 0 | HP8: 0 | HT8: =H8 -> 1 | HU8: =P8 -> 1 | HV8: =X8 -> 1 | HW8: =AF8 -> 1 | HX8: =AN8 -> 1 | HY8: =AW8 -> 2 | HZ8: =BR8 -> 2 | IA8: =CN8 -> 2 | IB8: =DL8 -> 2 | IC8: =EM8 -> 2 | ID8: =FP8 -> 2 | IE8: =GT8 -> 2 | JB8: =SUM(I8:L8) -> 1 | JC8: =SUM(Q8:T8) -> 1 | JD8: =SUM(Y8:AB8) -> 1 | JE8: =SUM(AG8:AJ8) -> 1 | JF8: =SUM(AO8:AR8) -> 1 | JG8: =SUM(AX8:BE8) -> 2 | JH8: =SUM(BS8:BZ8) -> 2 | JI8: =SUM(CO8:CV8) -> 2 | JJ8: =SUM(DO8:DV8) -> 2 | JK8: =SUM(EP8:FA8) -> 2 | JL8: =SUM(FS8:FZ8) -> 2 | JM8: =SUM(GW8:HD8) -> 2 | JO8: =H8 -> 1 | JP8: 1 | JQ8: 1 | JR8: 1 | JS8: 1 | JV8: =IA8-JI8 -> 0 | JW8: =IB8-JJ8 -> 0 | JX8: =IC8-JK8 -> 0 | KB8: =JB8-JO8 -> 0 | KC8: =JC8-JP8 -> 0 | KD8: =JD8-JQ8 -> 0 | KE8: =JE8-JR8 -> 0 | KF8: =JF8-JS8 -> 0 | KG8: =JG8-JT8 -> 2 | KH8: =JH8-JU8 -> 2 | KI8: =JI8-JV8 -> 2 | ... KM8: =JM8-JZ8 -> 2
A9: 2 | B9: SEMARANG TENGAH | C9: 3374130 | D9: MIROTO | E9: Brumbungan | F9: 2 | G9: 176 | H9: 5 | K9: 1 | L9: 4 | M9: 0 | N9: 0 | O9: =H9-(M9+N9) -> 5 | P9: 4 | S9: 1 | T9: 3 | U9: 0 | V9: 1 | W9: =P9-(U9+V9) -> 3 | X9: 4 | AA9: 1 | AB9: 3 | AC9: 0 | AD9: 0 | AE9: =X9-(AC9+AD9) -> 4 | AF9: 3 | AI9: 1 | AJ9: 2 | AK9: 0 | AL9: 1 | AM9: =AF9-(AK9+AL9) -> 2 | AN9: 4 | AQ9: 1 | AR9: 3 | AS9: 1 | AT9: 0 | AU9: =AN9-(AS9+AT9) -> 3 | AV9: 138 | AW9: =SUM(AX9:BE9) -> 3 | AX9: 0 | AY9: 0 | AZ9: 1 | BA9: 1 | BB9: 0 | BC9: 0 | BD9: 1 | BE9: 0 | BF9: 0 | BG9: 0 | BH9: 0 | BI9: 1 | BJ9: 0 | BK9: 0 | BL9: 0 | BM9: 0 | BN9: 1 | BO9: 0 | BP9: =SUM(BF9:BO9) -> 2 | BQ9: 141 | BR9: =SUM(BS9:BZ9) -> 3 | BS9: 0 | BT9: 0 | BU9: 1 | BV9: 2 | BW9: 0 | BX9: 0 | BY9: 0 | BZ9: 0 | CA9: 0 | CB9: 0 | CC9: 0 | CD9: 0 | CE9: 0 | CF9: 0 | CG9: 0 | CH9: 0 | CI9: 0 | CJ9: 0 | CK9: =SUM(CA9:CJ9) -> 0 | CL9: 142 | CM9: 46 | CN9: =SUM(CO9:CV9) -> 3 | CO9: 0 | CP9: 0 | CQ9: 1 | CR9: 2 | CS9: 0 | CT9: 0 | CU9: 0 | CV9: 0 | CW9: 0 | CX9: 0 | CY9: 0 | CZ9: 0 | DA9: 0 | DB9: 0 | DC9: 0 | DD9: 0 | DE9: 0 | DF9: 0 | DG9: =SUM(CW9:DF9) -> 0 | DH9: 114 | DI9: 47 | DJ9: 114 | DK9: 47 | DL9: =SUM(DO9:DV9) -> 2 | DM9: =(DO9+DP9+DQ9+DS9+DT9+DU9) -> 0 | DN9: =DR9+DV9 -> 2 | DO9: 0 | DP9: 0 | DQ9: 0 | DR9: 2 | DS9: 0 | DT9: 0 | DU9: 0 | DV9: 0 | DW9: 0 | DX9: 0 | DY9: 1 | DZ9: 0 | EA9: 0 | EB9: 0 | EC9: 0 | ED9: 0 | EE9: 0 | EF9: 0 | EG9: =SUM(DW9:EF9) -> 1 | EH9: =DW9+DX9+DY9+EA9+EB9+EC9+EE9+EF9 -> 1 | EI9: 114 | EJ9: 49 | EK9: 114 | EL9: 49 | EM9: =SUM(EP9:EW9) -> 2 | EN9: =(EP9+EQ9+ER9+ET9+EU9+EV9) -> 0 | EO9: =ES9+EW9 -> 2 | EP9: 0 | EQ9: 0 | ER9: 0 | ES9: 2 | ET9: 0 | EU9: 0 | EV9: 0 | EW9: 0 | EX9: 0 | EY9: 0 | EZ9: 0 | FA9: 0 | FB9: 0 | FC9: 0 | FD9: 0 | FE9: 0 | FF9: 0 | FG9: 0 | FH9: =SUM(EX9:FG9) -> 0 | FI9: =EX9+EY9+EZ9+FB9+FC9+FD9 -> 0 | FJ9: 112 | FK9: 45 | FL9: 112 | FM9: 45 | FO9: 3 | FP9: =SUM(FS9:FZ9) -> 3 | FQ9: 1 | FR9: 2 | FS9: 0 | FT9: 0 | FU9: 1 | FV9: 2 | FW9: 0 | FX9: 0 | FY9: 0 | FZ9: 0 | GA9: 0 | GB9: 0 | GC9: 0 | GD9: 0 | GE9: 0 | GF9: 0 | GG9: 0 | GH9: 0 | GI9: 0 | GJ9: 0 | GK9: 0 | GL9: 0 | GM9: 113 | GN9: 42 | GO9: 113 | GP9: 40 | GR9: 2 | GS9: 0 | GT9: =GU9+GV9 -> 2 | GU9: =GW9+GX9+GY9+HA9+HB9+HC9 -> 0 | GV9: =GZ9+HD9 -> 2 | GW9: 0 | GX9: 0 | GY9: 0 | GZ9: 2 | HA9: 0 | HB9: 0 | HC9: 0 | HD9: 0 | HE9: 0 | HF9: 0 | HG9: 1 | HH9: 0 | HI9: 0 | HJ9: 0 | HK9: 0 | HL9: 0 | HM9: 0 | HN9: 0 | HO9: 0 | HP9: 1 | HT9: =H9 -> 5 | HU9: =P9 -> 4 | HV9: =X9 -> 4 | HW9: =AF9 -> 3 | HX9: =AN9 -> 4 | HY9: =AW9 -> 3 | HZ9: =BR9 -> 3 | IA9: =CN9 -> 3 | IB9: =DL9 -> 2 | IC9: =EM9 -> 2 | ID9: =FP9 -> 3 | IE9: =GT9 -> 2 | JB9: =SUM(I9:L9) -> 5 | JC9: =SUM(Q9:T9) -> 4 | JD9: =SUM(Y9:AB9) -> 4 | JE9: =SUM(AG9:AJ9) -> 3 | JF9: =SUM(AO9:AR9) -> 4 | JG9: =SUM(AX9:BE9) -> 3 | JH9: =SUM(BS9:BZ9) -> 3 | JI9: =SUM(CO9:CV9) -> 3 | JJ9: =SUM(DO9:DV9) -> 2 | JK9: =SUM(EP9:FA9) -> 2 | JL9: =SUM(FS9:FZ9) -> 3 | JM9: =SUM(GW9:HD9) -> 2 | JO9: =H9 -> 5 | JP9: 4 | JQ9: 4 | JR9: 3 | JS9: 4 | JV9: =IA9-JI9 -> 0 | JW9: =IB9-JJ9 -> 0 | JX9: =IC9-JK9 -> 0 | KB9: =JB9-JO9 -> 0 | KC9: =JC9-JP9 -> 0 | KD9: =JD9-JQ9 -> 0 | KE9: =JE9-JR9 -> 0 | KF9: =JF9-JS9 -> 0 | KG9: =JG9-JT9 -> 3 | KH9: =JH9-JU9 -> 3 | KI9: =JI9-JV9 -> 3 | ... KM9: =JM9-JZ9 -> 2
A10: 3 | B10: SEMARANG TENGAH | C10: 3374130 | D10: MIROTO | E10: Jagalan | F10: 6 | G10: 233 | H10: 3 | L10: 3 | M10: 0 | N10: 0 | O10: =H10-(M10+N10) -> 3 | P10: 3 | S10: 1 | T10: 2 | U10: 1 | V10: 1 | W10: =P10-(U10+V10) -> 1 | X10: 4 | AA10: 2 | AB10: 2 | AC10: 0 | AD10: 2 | AE10: =X10-(AC10+AD10) -> 2 | AF10: 1 | AJ10: 1 | AK10: 0 | AL10: 0 | AM10: =AF10-(AK10+AL10) -> 1 | AN10: 1 | AR10: 1 | AS10: 0 | AT10: 0 | AU10: =AN10-(AS10+AT10) -> 1 | AV10: 212 | AW10: =SUM(AX10:BE10) -> 3 | AX10: 0 | AY10: 0 | AZ10: 0 | BA10: 2 | BB10: 0 | BC10: 0 | BD10: 1 | BE10: 0 | BF10: 0 | BG10: 0 | BH10: 0 | BI10: 0 | BJ10: 0 | BK10: 0 | BL10: 0 | BM10: 0 | BN10: 0 | BO10: 0 | BP10: =SUM(BF10:BO10) -> 0 | BQ10: 216 | BR10: =SUM(BS10:BZ10) -> 2 | BS10: 0 | BT10: 0 | BU10: 1 | BV10: 1 | BW10: 0 | BX10: 0 | BY10: 0 | BZ10: 0 | CA10: 0 | CB10: 0 | CC10: 0 | CD10: 1 | CE10: 0 | CF10: 0 | CG10: 0 | CH10: 0 | CI10: 0 | CJ10: 0 | CK10: =SUM(CA10:CJ10) -> 1 | CL10: 220 | CM10: 76 | CN10: =SUM(CO10:CV10) -> 2 | CO10: 0 | CP10: 0 | CQ10: 1 | CR10: 1 | CS10: 0 | CT10: 0 | CU10: 0 | CV10: 0 | CW10: 0 | CX10: 0 | CY10: 0 | CZ10: 0 | DA10: 0 | DB10: 0 | DC10: 0 | DD10: 0 | DE10: 0 | DF10: 0 | DG10: =SUM(CW10:DF10) -> 0 | DH10: 198 | DI10: 73 | DJ10: 198 | DK10: 73 | DL10: =SUM(DO10:DV10) -> 3 | DM10: =(DO10+DP10+DQ10+DS10+DT10+DU10) -> 2 | DN10: =DR10+DV10 -> 1 | DO10: 0 | DP10: 0 | DQ10: 1 | DR10: 1 | DS10: 0 | DT10: 0 | DU10: 1 | DV10: 0 | DW10: 0 | DX10: 0 | DY10: 0 | DZ10: 0 | EA10: 0 | EB10: 0 | EC10: 0 | ED10: 0 | EE10: 0 | EF10: 0 | EG10: =SUM(DW10:EF10) -> 0 | EH10: =DW10+DX10+DY10+EA10+EB10+EC10+EE10+EF10 -> 0 | EI10: 201 | EJ10: 75 | EK10: 201 | EL10: 75 | EM10: =SUM(EP10:EW10) -> 3 | EN10: =(EP10+EQ10+ER10+ET10+EU10+EV10) -> 2 | EO10: =ES10+EW10 -> 1 | EP10: 0 | EQ10: 0 | ER10: 2 | ES10: 1 | ET10: 0 | EU10: 0 | EV10: 0 | EW10: 0 | EX10: 0 | EY10: 0 | EZ10: 0 | FA10: 0 | FB10: 0 | FC10: 0 | FD10: 0 | FE10: 0 | FF10: 0 | FG10: 0 | FH10: =SUM(EX10:FG10) -> 0 | FI10: =EX10+EY10+EZ10+FB10+FC10+FD10 -> 0 | FJ10: 190 | FK10: 67 | FL10: 190 | FM10: 67 | FO10: 3 | FP10: =SUM(FS10:FZ10) -> 3 | FQ10: 1 | FR10: 2 | FS10: 0 | FT10: 0 | FU10: 1 | FV10: 2 | FW10: 0 | FX10: 0 | FY10: 0 | FZ10: 0 | GA10: 0 | GB10: 0 | GC10: 0 | GD10: 0 | GE10: 0 | GF10: 0 | GG10: 0 | GH10: 0 | GI10: 0 | GJ10: 0 | GK10: 0 | GL10: 0 | GM10: 190 | GN10: 68 | GO10: 190 | GP10: 67 | GR10: 3 | GS10: 1 | GT10: =GU10+GV10 -> 3 | GU10: =GW10+GX10+GY10+HA10+HB10+HC10 -> 1 | GV10: =GZ10+HD10 -> 2 | GW10: 0 | GX10: 0 | GY10: 1 | GZ10: 2 | HA10: 0 | HB10: 0 | HC10: 0 | HD10: 0 | HE10: 0 | HF10: 0 | HG10: 0 | HH10: 0 | HI10: 0 | HJ10: 0 | HK10: 0 | HL10: 0 | HM10: 0 | HN10: 0 | HO10: 0 | HP10: 0 | HT10: =H10 -> 3 | HU10: =P10 -> 3 | HV10: =X10 -> 4 | HW10: =AF10 -> 1 | HX10: =AN10 -> 1 | HY10: =AW10 -> 3 | HZ10: =BR10 -> 2 | IA10: =CN10 -> 2 | IB10: =DL10 -> 3 | IC10: =EM10 -> 3 | ID10: =FP10 -> 3 | IE10: =GT10 -> 3 | JB10: =SUM(I10:L10) -> 3 | JC10: =SUM(Q10:T10) -> 3 | JD10: =SUM(Y10:AB10) -> 4 | JE10: =SUM(AG10:AJ10) -> 1 | JF10: =SUM(AO10:AR10) -> 1 | JG10: =SUM(AX10:BE10) -> 3 | JH10: =SUM(BS10:BZ10) -> 2 | JI10: =SUM(CO10:CV10) -> 2 | JJ10: =SUM(DO10:DV10) -> 3 | JK10: =SUM(EP10:FA10) -> 3 | JL10: =SUM(FS10:FZ10) -> 3 | JM10: =SUM(GW10:HD10) -> 3 | JO10: =H10 -> 3 | JP10: 3 | JQ10: 4 | JR10: 1 | JS10: 1 | JV10: =IA10-JI10 -> 0 | JW10: =IB10-JJ10 -> 0 | JX10: =IC10-JK10 -> 0 | KB10: =JB10-JO10 -> 0 | KC10: =JC10-JP10 -> 0 | KD10: =JD10-JQ10 -> 0 | KE10: =JE10-JR10 -> 0 | KF10: =JF10-JS10 -> 0 | KG10: =JG10-JT10 -> 3 | KH10: =JH10-JU10 -> 2 | KI10: =JI10-JV10 -> 2 | ... KM10: =JM10-JZ10 -> 3
A11: 4 | B11: SEMARANG TENGAH | C11: 3374130 | D11: PONCOL | E11: Kranggan | F11: 2 | G11: 98 | H11: 3 | I11: 0 | J11: 0 | K11: 1 | L11: 2 | M11: 2 | N11: 0 | O11: =H11-(M11+N11) -> 1 | P11: 9 | Q11: 0 | R11: 2 | S11: 3 | T11: 4 | U11: 4 | V11: 1 | W11: =P11-(U11+V11) -> 4 | X11: 7 | Y11: 0 | Z11: 1 | AA11: 3 | AB11: 3 | AC11: 0 | AD11: 1 | AE11: =X11-(AC11+AD11) -> 6 | AF11: 10 | AG11: 0 | AH11: 2 | AI11: 5 | AJ11: 3 | AK11: 3 | AL11: 0 | AM11: =AF11-(AK11+AL11) -> 7 | AN11: 8 | AO11: 0 | AP11: 1 | AQ11: 4 | AR11: 3 | AS11: 0 | AT11: 2 | AU11: =AN11-(AS11+AT11) -> 6 | AV11: 72 | AW11: =SUM(AX11:BE11) -> 7 | AX11: 0 | AY11: 0 | AZ11: 4 | BA11: 2 | BB11: 0 | BC11: 0 | BD11: 1 | BE11: 0 | BF11: 0 | BG11: 0 | BH11: 1 | BI11: 0 | BJ11: 0 | BK11: 0 | BL11: 0 | BM11: 0 | BN11: 0 | BO11: 0 | BP11: =SUM(BF11:BO11) -> 1 | BQ11: 70 | BR11: =SUM(BS11:BZ11) -> 6 | BS11: 0 | BT11: 0 | BU11: 4 | BV11: 2 | BW11: 0 | BX11: 0 | BY11: 0 | BZ11: 0 | CA11: 0 | CB11: 0 | CC11: 0 | CD11: 0 | CE11: 0 | CF11: 0 | CG11: 0 | CH11: 0 | CI11: 0 | CJ11: 0 | CK11: =SUM(CA11:CJ11) -> 0 | CL11: 69 | CM11: 52 | CN11: =SUM(CO11:CV11) -> 6 | CO11: 0 | CP11: 0 | CQ11: 3 | CR11: 1 | CS11: 0 | CT11: 1 | CU11: 1 | CV11: 0 | CW11: 0 | CX11: 0 | CY11: 1 | CZ11: 0 | DA11: 0 | DB11: 0 | DC11: 0 | DD11: 0 | DE11: 1 | DF11: 0 | DG11: =SUM(CW11:DF11) -> 2 | DH11: 108 | DI11: 45 | DJ11: 103 | DK11: 39 | DL11: =SUM(DO11:DV11) -> 8 | DM11: =(DO11+DP11+DQ11+DS11+DT11+DU11) -> 1 | DN11: =DR11+DV11 -> 7 | DO11: 0 | DP11: 0 | DQ11: 1 | DR11: 1 | DS11: 0 | DT11: 0 | DU11: 0 | DV11: 6 | DW11: 0 | DX11: 1 | DY11: 2 | DZ11: 1 | EA11: 0 | EB11: 0 | EC11: 0 | ED11: 0 | EE11: 0 | EF11: 0 | EG11: =SUM(DW11:EF11) -> 4 | EH11: =DW11+DX11+DY11+EA11+EB11+EC11+EE11+EF11 -> 3 | EI11: 71 | EJ11: 41 | EK11: 69 | EL11: 38 | EM11: =SUM(EP11:EW11) -> 6 | EN11: =(EP11+EQ11+ER11+ET11+EU11+EV11) -> 1 | EO11: =ES11+EW11 -> 5 | EP11: 0 | EQ11: 0 | ER11: 0 | ES11: 5 | ET11: 0 | EU11: 0 | EV11: 1 | EW11: 0 | EX11: 0 | EY11: 0 | EZ11: 0 | FA11: 3 | FB11: 0 | FC11: 0 | FD11: 0 | FE11: 0 | FF11: 0 | FG11: 0 | FH11: =SUM(EX11:FG11) -> 3 | FI11: =EX11+EY11+EZ11+FB11+FC11+FD11 -> 0 | FJ11: 66 | FK11: 24 | FL11: 66 | FM11: 24 | FO11: 7 | FP11: =SUM(FS11:FZ11) -> 7 | FQ11: 0 | FR11: 7 | FS11: 0 | FT11: 0 | FU11: 0 | FV11: 5 | FW11: 0 | FX11: 0 | FY11: 0 | FZ11: 2 | GA11: 0 | GB11: 0 | GC11: 0 | GD11: 2 | GE11: 0 | GF11: 0 | GG11: 0 | GH11: 0 | GI11: 0 | GJ11: 0 | GK11: 2 | GL11: 0 | GM11: 64 | GN11: 24 | GO11: 54 | GP11: 15 | GR11: 8 | GS11: 0 | GT11: =GU11+GV11 -> 8 | GU11: =GW11+GX11+GY11+HA11+HB11+HC11 -> 0 | GV11: =GZ11+HD11 -> 8 | GW11: 0 | GX11: 0 | GY11: 0 | GZ11: 7 | HA11: 0 | HB11: 0 | HC11: 0 | HD11: 1 | HE11: 0 | HF11: 0 | HG11: 0 | HH11: 0 | HI11: 0 | HJ11: 0 | HK11: 0 | HL11: 0 | HM11: 0 | HN11: 0 | HT11: =H11 -> 3 | HU11: =P11 -> 9 | HV11: =X11 -> 7 | HW11: =AF11 -> 10 | HX11: =AN11 -> 8 | HY11: =AW11 -> 7 | HZ11: =BR11 -> 6 | IA11: =CN11 -> 6 | IB11: =DL11 -> 8 | IC11: =EM11 -> 6 | ID11: =FP11 -> 7 | IE11: =GT11 -> 8 | JB11: =SUM(I11:L11) -> 3 | JC11: =SUM(Q11:T11) -> 9 | JD11: =SUM(Y11:AB11) -> 7 | JE11: =SUM(AG11:AJ11) -> 10 | JF11: =SUM(AO11:AR11) -> 8 | JG11: =SUM(AX11:BE11) -> 7 | JH11: =SUM(BS11:BZ11) -> 6 | JI11: =SUM(CO11:CV11) -> 6 | JJ11: =SUM(DO11:DV11) -> 8 | JK11: =SUM(EP11:FA11) -> 9 | JL11: =SUM(FS11:FZ11) -> 7 | JM11: =SUM(GW11:HD11) -> 8 | JO11: =H11 -> 3 | JP11: 9 | JQ11: 7 | JR11: 10 | JS11: 8 | JV11: =IA11-JI11 -> 0 | JW11: =IB11-JJ11 -> 0 | JX11: =IC11-JK11 -> -3 | KB11: =JB11-JO11 -> 0 | KC11: =JC11-JP11 -> 0 | KD11: =JD11-JQ11 -> 0 | KE11: =JE11-JR11 -> 0 | KF11: =JF11-JS11 -> 0 | KG11: =JG11-JT11 -> 7 | KH11: =JH11-JU11 -> 6 | KI11: =JI11-JV11 -> 6 | ... KM11: =JM11-JZ11 -> 8
A12: 5 | B12: SEMARANG TENGAH | C12: 3374130 | D12: MIROTO | E12: Gabahan | F12: 7 | G12: 315 | H12: 3 | L12: 3 | M12: 0 | N12: 0 | O12: =H12-(M12+N12) -> 3 | P12: 3 | T12: 3 | U12: 0 | V12: 2 | W12: =P12-(U12+V12) -> 1 | X12: 2 | AB12: 2 | AC12: 0 | AD12: 0 | AE12: =X12-(AC12+AD12) -> 2 | AF12: 4 | AJ12: 4 | AK12: 0 | AL12: 1 | AM12: =AF12-(AK12+AL12) -> 3 | AN12: 3 | AO12: 1 | AR12: 2 | AS12: 0 | AT12: 0 | AU12: =AN12-(AS12+AT12) -> 3 | AV12: 258 | AW12: =SUM(AX12:BE12) -> 4 | AX12: 1 | AY12: 0 | AZ12: 1 | BA12: 2 | BB12: 0 | BC12: 0 | BD12: 0 | BE12: 0 | BF12: 0 | BG12: 0 | BH12: 0 | BI12: 0 | BJ12: 0 | BK12: 0 | BL12: 0 | BM12: 0 | BN12: 0 | BO12: 0 | BP12: =SUM(BF12:BO12) -> 0 | BQ12: 254 | BR12: =SUM(BS12:BZ12) -> 4 | BS12: 1 | BT12: 0 | BU12: 1 | BV12: 2 | BW12: 0 | BX12: 0 | BY12: 0 | BZ12: 0 | CA12: 0 | CB12: 0 | CC12: 0 | CD12: 0 | CE12: 0 | CF12: 0 | CG12: 0 | CH12: 0 | CI12: 0 | CJ12: 0 | CK12: =SUM(CA12:CJ12) -> 0 | CL12: 248 | CM12: 70 | CN12: =SUM(CO12:CV12) -> 5 | CO12: 1 | CP12: 0 | CQ12: 0 | CR12: 3 | CS12: 0 | CT12: 0 | CU12: 0 | CV12: 1 | CW12: 0 | CX12: 0 | CY12: 0 | CZ12: 0 | DA12: 0 | DB12: 0 | DC12: 0 | DD12: 0 | DE12: 0 | DF12: 0 | DG12: =SUM(CW12:DF12) -> 0 | DH12: 231 | DI12: 70 | DJ12: 231 | DK12: 70 | DL12: =SUM(DO12:DV12) -> 5 | DM12: =(DO12+DP12+DQ12+DS12+DT12+DU12) -> 1 | DN12: =DR12+DV12 -> 4 | DO12: 1 | DP12: 0 | DQ12: 0 | DR12: 4 | DS12: 0 | DT12: 0 | DU12: 0 | DV12: 0 | DW12: 0 | DX12: 0 | DY12: 0 | DZ12: 0 | EA12: 0 | EB12: 0 | EC12: 0 | ED12: 0 | EE12: 0 | EF12: 0 | EG12: =SUM(DW12:EF12) -> 0 | EH12: =DW12+DX12+DY12+EA12+EB12+EC12+EE12+EF12 -> 0 | EI12: 224 | EJ12: 70 | EK12: 224 | EL12: 70 | EM12: =SUM(EP12:EW12) -> 4 | EN12: =(EP12+EQ12+ER12+ET12+EU12+EV12) -> 1 | EO12: =ES12+EW12 -> 3 | EP12: 1 | EQ12: 0 | ER12: 0 | ES12: 3 | ET12: 0 | EU12: 0 | EV12: 0 | EW12: 0 | EX12: 0 | EY12: 0 | EZ12: 0 | FA12: 1 | FB12: 0 | FC12: 0 | FD12: 0 | FE12: 0 | FF12: 0 | FG12: 0 | FH12: =SUM(EX12:FG12) -> 1 | FI12: =EX12+EY12+EZ12+FB12+FC12+FD12 -> 0 | FJ12: 222 | FK12: 70 | FL12: 222 | FM12: 70 | FO12: 4 | FP12: =SUM(FS12:FZ12) -> 4 | FQ12: 1 | FR12: 3 | FS12: 1 | FT12: 0 | FU12: 0 | FV12: 3 | FW12: 0 | FX12: 0 | FY12: 0 | FZ12: 0 | GA12: 0 | GB12: 0 | GC12: 0 | GD12: 0 | GE12: 0 | GF12: 0 | GG12: 0 | GH12: 0 | GI12: 0 | GJ12: 0 | GK12: 0 | GL12: 0 | GM12: 214 | GN12: 64 | GO12: 214 | GP12: 64 | GR12: 3 | GS12: 0 | GT12: =GU12+GV12 -> 3 | GU12: =GW12+GX12+GY12+HA12+HB12+HC12 -> 0 | GV12: =GZ12+HD12 -> 3 | GW12: 0 | GX12: 0 | GY12: 0 | GZ12: 3 | HA12: 0 | HB12: 0 | HC12: 0 | HD12: 0 | HE12: 0 | HF12: 1 | HG12: 0 | HH12: 0 | HI12: 0 | HJ12: 0 | HK12: 0 | HL12: 0 | HM12: 0 | HN12: 0 | HO12: 0 | HP12: 1 | HT12: =H12 -> 3 | HU12: =P12 -> 3 | HV12: =X12 -> 2 | HW12: =AF12 -> 4 | HX12: =AN12 -> 3 | HY12: =AW12 -> 4 | HZ12: =BR12 -> 4 | IA12: =CN12 -> 5 | IB12: =DL12 -> 5 | IC12: =EM12 -> 4 | ID12: =FP12 -> 4 | IE12: =GT12 -> 3 | JB12: =SUM(I12:L12) -> 3 | JC12: =SUM(Q12:T12) -> 3 | JD12: =SUM(Y12:AB12) -> 2 | JE12: =SUM(AG12:AJ12) -> 4 | JF12: =SUM(AO12:AR12) -> 3 | JG12: =SUM(AX12:BE12) -> 4 | JH12: =SUM(BS12:BZ12) -> 4 | JI12: =SUM(CO12:CV12) -> 5 | JJ12: =SUM(DO12:DV12) -> 5 | JK12: =SUM(EP12:FA12) -> 5 | JL12: =SUM(FS12:FZ12) -> 4 | JM12: =SUM(GW12:HD12) -> 3 | JO12: =H12 -> 3 | JP12: 3 | JQ12: 2 | JR12: 4 | JS12: 3 | JV12: =IA12-JI12 -> 0 | JW12: =IB12-JJ12 -> 0 | JX12: =IC12-JK12 -> -1 | KB12: =JB12-JO12 -> 0 | KC12: =JC12-JP12 -> 0 | KD12: =JD12-JQ12 -> 0 | KE12: =JE12-JR12 -> 0 | KF12: =JF12-JS12 -> 0 | KG12: =JG12-JT12 -> 4 | KH12: =JH12-JU12 -> 4 | KI12: =JI12-JV12 -> 5 | ... KM12: =JM12-JZ12 -> 3
A13: 6 | B13: SEMARANG TENGAH | C13: 3374130 | D13: PONCOL | E13: Kembangsari | F13: 4 | G13: 158 | H13: 4 | I13: 1 | J13: 0 | K13: 0 | L13: 3 | M13: 1 | N13: 0 | O13: =H13-(M13+N13) -> 3 | P13: 8 | Q13: 2 | R13: 1 | S13: 0 | T13: 5 | U13: 4 | V13: 0 | W13: =P13-(U13+V13) -> 4 | X13: 6 | Y13: 1 | Z13: 1 | AA13: 0 | AB13: 4 | AC13: 0 | AD13: 1 | AE13: =X13-(AC13+AD13) -> 5 | AF13: 7 | AG13: 0 | AH13: 2 | AI13: 1 | AJ13: 4 | AK13: 1 | AL13: 0 | AM13: =AF13-(AK13+AL13) -> 6 | AN13: 5 | AO13: 0 | AP13: 2 | AQ13: 1 | AR13: 2 | AS13: 0 | AT13: 2 | AU13: =AN13-(AS13+AT13) -> 3 | AV13: 117 | AW13: =SUM(AX13:BE13) -> 4 | AX13: 0 | AY13: 1 | AZ13: 2 | BA13: 1 | BB13: 0 | BC13: 0 | BD13: 0 | BE13: 0 | BF13: 0 | BG13: 0 | BH13: 0 | BI13: 1 | BJ13: 0 | BK13: 0 | BL13: 0 | BM13: 0 | BN13: 0 | BO13: 0 | BP13: =SUM(BF13:BO13) -> 1 | BQ13: 115 | BR13: =SUM(BS13:BZ13) -> 3 | BS13: 0 | BT13: 1 | BU13: 1 | BV13: 1 | BW13: 0 | BX13: 0 | BY13: 0 | BZ13: 0 | CA13: 0 | CB13: 0 | CC13: 2 | CD13: 0 | CE13: 0 | CF13: 0 | CG13: 0 | CH13: 0 | CI13: 0 | CJ13: 0 | CK13: =SUM(CA13:CJ13) -> 2 | CL13: 110 | CM13: 48 | CN13: =SUM(CO13:CV13) -> 2 | CO13: 0 | CP13: 1 | CQ13: 0 | CR13: 1 | CS13: 0 | CT13: 0 | CU13: 0 | CV13: 0 | CW13: 0 | CX13: 0 | CY13: 1 | CZ13: 0 | DA13: 0 | DB13: 0 | DC13: 0 | DD13: 0 | DE13: 0 | DF13: 0 | DG13: =SUM(CW13:DF13) -> 1 | DH13: 109 | DI13: 47 | DJ13: 108 | DK13: 48 | DL13: =SUM(DO13:DV13) -> 12 | DM13: =(DO13+DP13+DQ13+DS13+DT13+DU13) -> 4 | DN13: =DR13+DV13 -> 8 | DO13: 0 | DP13: 0 | DQ13: 0 | DR13: 0 | DS13: 0 | DT13: 0 | DU13: 4 | DV13: 8 | DW13: 0 | DX13: 1 | DY13: 0 | DZ13: 1 | EA13: 0 | EB13: 0 | EC13: 0 | ED13: 0 | EE13: 0 | EF13: 0 | EG13: =SUM(DW13:EF13) -> 2 | EH13: =DW13+DX13+DY13+EA13+EB13+EC13+EE13+EF13 -> 1 | EI13: 106 | EJ13: 49 | EK13: 104 | EL13: 48 | EM13: =SUM(EP13:EW13) -> 5 | EN13: =(EP13+EQ13+ER13+ET13+EU13+EV13) -> 2 | EO13: =ES13+EW13 -> 3 | EP13: 0 | EQ13: 0 | ER13: 2 | ES13: 3 | ET13: 0 | EU13: 0 | EV13: 0 | EW13: 0 | EX13: 0 | EY13: 0 | EZ13: 1 | FA13: 5 | FB13: 0 | FC13: 0 | FD13: 0 | FE13: 0 | FF13: 1 | FG13: 0 | FH13: =SUM(EX13:FG13) -> 7 | FI13: =EX13+EY13+EZ13+FB13+FC13+FD13 -> 1 | FJ13: 98 | FK13: 31 | FL13: 98 | FM13: 31 | FO13: 5 | FP13: =SUM(FS13:FZ13) -> 5 | FQ13: 2 | FR13: 3 | FS13: 0 | FT13: 0 | FU13: 1 | FV13: 3 | FW13: 0 | FX13: 0 | FY13: 1 | FZ13: 0 | GA13: 0 | GB13: 0 | GC13: 1 | GD13: 0 | GE13: 0 | GF13: 0 | GG13: 0 | GH13: 0 | GI13: 0 | GJ13: 0 | GK13: 1 | GL13: 1 | GM13: 116 | GN13: 39 | GO13: 116 | GP13: 39 | GR13: 6 | GS13: 3 | GT13: =GU13+GV13 -> 6 | GU13: =GW13+GX13+GY13+HA13+HB13+HC13 -> 3 | GV13: =GZ13+HD13 -> 3 | GW13: 0 | GX13: 0 | GY13: 2 | GZ13: 3 | HA13: 0 | HB13: 0 | HC13: 1 | HD13: 0 | HE13: 0 | HF13: 0 | HG13: 0 | HH13: 0 | HI13: 0 | HJ13: 0 | HK13: 0 | HL13: 0 | HM13: 0 | HN13: 0 | HT13: =H13 -> 4 | HU13: =P13 -> 8 | HV13: =X13 -> 6 | HW13: =AF13 -> 7 | HX13: =AN13 -> 5 | HY13: =AW13 -> 4 | HZ13: =BR13 -> 3 | IA13: =CN13 -> 2 | IB13: =DL13 -> 12 | IC13: =EM13 -> 5 | ID13: =FP13 -> 5 | IE13: =GT13 -> 6 | JB13: =SUM(I13:L13) -> 4 | JC13: =SUM(Q13:T13) -> 8 | JD13: =SUM(Y13:AB13) -> 6 | JE13: =SUM(AG13:AJ13) -> 7 | JF13: =SUM(AO13:AR13) -> 5 | JG13: =SUM(AX13:BE13) -> 4 | JH13: =SUM(BS13:BZ13) -> 3 | JI13: =SUM(CO13:CV13) -> 2 | JJ13: =SUM(DO13:DV13) -> 12 | JK13: =SUM(EP13:FA13) -> 11 | JL13: =SUM(FS13:FZ13) -> 5 | JM13: =SUM(GW13:HD13) -> 6 | JO13: =H13 -> 4 | JP13: 8 | JQ13: 6 | JR13: 7 | JS13: 5 | JV13: =IA13-JI13 -> 0 | JW13: =IB13-JJ13 -> 0 | JX13: =IC13-JK13 -> -6 | KB13: =JB13-JO13 -> 0 | KC13: =JC13-JP13 -> 0 | KD13: =JD13-JQ13 -> 0 | KE13: =JE13-JR13 -> 0 | KF13: =JF13-JS13 -> 0 | KG13: =JG13-JT13 -> 4 | KH13: =JH13-JU13 -> 3 | KI13: =JI13-JV13 -> 2 | ... KM13: =JM13-JZ13 -> 6
A14: 7 | B14: SEMARANG TENGAH | C14: 3374130 | D14: PONCOL | E14: Sekayu | F14: 2 | G14: 136 | H14: 7 | I14: 0 | J14: 0 | K14: 3 | L14: 4 | M14: 3 | N14: 0 | O14: =H14-(M14+N14) -> 4 | P14: 9 | Q14: 0 | R14: 1 | S14: 4 | T14: 4 | U14: 4 | V14: 1 | W14: =P14-(U14+V14) -> 4 | X14: 11 | Y14: 0 | Z14: 3 | AA14: 4 | AB14: 4 | AC14: 1 | AD14: 0 | AE14: =X14-(AC14+AD14) -> 10 | AF14: 13 | AG14: 0 | AH14: 3 | AI14: 5 | AJ14: 5 | AK14: 2 | AL14: 0 | AM14: =AF14-(AK14+AL14) -> 11 | AN14: 11 | AO14: 0 | AP14: 1 | AQ14: 4 | AR14: 6 | AS14: 0 | AT14: 2 | AU14: =AN14-(AS14+AT14) -> 9 | AV14: 147 | AW14: =SUM(AX14:BE14) -> 11 | AX14: 0 | AY14: 1 | AZ14: 4 | BA14: 5 | BB14: 0 | BC14: 1 | BD14: 0 | BE14: 0 | BF14: 0 | BG14: 0 | BH14: 0 | BI14: 0 | BJ14: 0 | BK14: 0 | BL14: 0 | BM14: 0 | BN14: 1 | BO14: 0 | BP14: =SUM(BF14:BO14) -> 1 | BQ14: 140 | BR14: =SUM(BS14:BZ14) -> 6 | BS14: 0 | BT14: 1 | BU14: 2 | BV14: 3 | BW14: 0 | BX14: 0 | BY14: 0 | BZ14: 0 | CA14: 0 | CB14: 1 | CC14: 2 | CD14: 2 | CE14: 0 | CF14: 0 | CG14: 0 | CH14: 0 | CI14: 0 | CJ14: 0 | CK14: =SUM(CA14:CJ14) -> 5 | CL14: 131 | CM14: 46 | CN14: =SUM(CO14:CV14) -> 7 | CO14: 0 | CP14: 0 | CQ14: 2 | CR14: 4 | CS14: 0 | CT14: 1 | CU14: 0 | CV14: 0 | CW14: 0 | CX14: 0 | CY14: 0 | CZ14: 0 | DA14: 0 | DB14: 0 | DC14: 0 | DD14: 0 | DE14: 0 | DF14: 0 | DG14: =SUM(CW14:DF14) -> 0 | DH14: 122 | DI14: 41 | DJ14: 120 | DK14: 36 | DL14: =SUM(DO14:DV14) -> 13 | DM14: =(DO14+DP14+DQ14+DS14+DT14+DU14) -> 4 | DN14: =DR14+DV14 -> 9 | DO14: 0 | DP14: 0 | DQ14: 2 | DR14: 0 | DS14: 0 | DT14: 0 | DU14: 2 | DV14: 9 | DW14: 0 | DX14: 1 | DY14: 0 | DZ14: 4 | EA14: 0 | EB14: 0 | EC14: 0 | ED14: 0 | EE14: 0 | EF14: 0 | EG14: =SUM(DW14:EF14) -> 5 | EH14: =DW14+DX14+DY14+EA14+EB14+EC14+EE14+EF14 -> 1 | EI14: 125 | EJ14: 32 | EK14: 123 | EL14: 31 | EM14: =SUM(EP14:EW14) -> 10 | EN14: =(EP14+EQ14+ER14+ET14+EU14+EV14) -> 3 | EO14: =ES14+EW14 -> 7 | EP14: 0 | EQ14: 0 | ER14: 3 | ES14: 7 | ET14: 0 | EU14: 0 | EV14: 0 | EW14: 0 | EX14: 0 | EY14: 0 | EZ14: 0 | FA14: 3 | FB14: 0 | FC14: 0 | FD14: 0 | FE14: 0 | FF14: 0 | FG14: 0 | FH14: =SUM(EX14:FG14) -> 3 | FI14: =EX14+EY14+EZ14+FB14+FC14+FD14 -> 0 | FJ14: 132 | FK14: 24 | FL14: 132 | FM14: 24 | FO14: 3 | FP14: =SUM(FS14:FZ14) -> 3 | FQ14: 3 | FR14: 0 | FS14: 0 | FT14: 0 | FU14: 2 | FV14: 0 | FW14: 0 | FX14: 0 | FY14: 1 | FZ14: 0 | GA14: 0 | GB14: 0 | GC14: 1 | GD14: 7 | GE14: 0 | GF14: 0 | GG14: 0 | GH14: 0 | GI14: 0 | GJ14: 0 | GK14: 8 | GL14: 1 | GM14: 156 | GN14: 47 | GO14: 156 | GP14: 47 | GR14: 1 | GS14: 1 | GT14: =GU14+GV14 -> 1 | GU14: =GW14+GX14+GY14+HA14+HB14+HC14 -> 1 | GV14: =GZ14+HD14 -> 0 | GW14: 0 | GX14: 0 | GY14: 1 | GZ14: 0 | HA14: 0 | HB14: 0 | HC14: 0 | HD14: 0 | HE14: 0 | HF14: 0 | HG14: 2 | HH14: 0 | HI14: 0 | HJ14: 0 | HK14: 0 | HL14: 0 | HM14: 0 | HN14: 0 | HT14: =H14 -> 7 | HU14: =P14 -> 9 | HV14: =X14 -> 11 | HW14: =AF14 -> 13 | HX14: =AN14 -> 11 | HY14: =AW14 -> 11 | HZ14: =BR14 -> 6 | IA14: =CN14 -> 7 | IB14: =DL14 -> 13 | IC14: =EM14 -> 10 | ID14: =FP14 -> 3 | IE14: =GT14 -> 1 | JB14: =SUM(I14:L14) -> 7 | JC14: =SUM(Q14:T14) -> 9 | JD14: =SUM(Y14:AB14) -> 11 | JE14: =SUM(AG14:AJ14) -> 13 | JF14: =SUM(AO14:AR14) -> 11 | JG14: =SUM(AX14:BE14) -> 11 | JH14: =SUM(BS14:BZ14) -> 6 | JI14: =SUM(CO14:CV14) -> 7 | JJ14: =SUM(DO14:DV14) -> 13 | JK14: =SUM(EP14:FA14) -> 13 | JL14: =SUM(FS14:FZ14) -> 3 | JM14: =SUM(GW14:HD14) -> 1 | JO14: =H14 -> 7 | JP14: 9 | JQ14: 11 | JR14: 13 | JS14: 11 | JV14: =IA14-JI14 -> 0 | JW14: =IB14-JJ14 -> 0 | JX14: =IC14-JK14 -> -3 | KB14: =JB14-JO14 -> 0 | KC14: =JC14-JP14 -> 0 | KD14: =JD14-JQ14 -> 0 | KE14: =JE14-JR14 -> 0 | KF14: =JF14-JS14 -> 0 | KG14: =JG14-JT14 -> 11 | KH14: =JH14-JU14 -> 6 | KI14: =JI14-JV14 -> 7 | ... KM14: =JM14-JZ14 -> 1
A15: 8 | B15: SEMARANG TENGAH | C15: 3374130 | D15: PONCOL | E15: Pandansari | F15: 4 | G15: 101 | H15: 5 | I15: 0 | J15: 1 | K15: 1 | L15: 3 | M15: 2 | N15: 0 | O15: =H15-(M15+N15) -> 3 | P15: 7 | Q15: 0 | R15: 1 | S15: 3 | T15: 3 | U15: 0 | V15: 0 | W15: =P15-(U15+V15) -> 7 | X15: 5 | Y15: 0 | Z15: 0 | AA15: 2 | AB15: 3 | AC15: 0 | AD15: 0 | AE15: =X15-(AC15+AD15) -> 5 | AF15: 5 | AG15: 0 | AH15: 0 | AI15: 2 | AJ15: 3 | AK15: 0 | AL15: 0 | AM15: =AF15-(AK15+AL15) -> 5 | AN15: 3 | AO15: 0 | AP15: 0 | AQ15: 1 | AR15: 2 | AS15: 0 | AT15: 2 | AU15: =AN15-(AS15+AT15) -> 1 | AV15: 88 | AW15: =SUM(AX15:BE15) -> 3 | AX15: 0 | AY15: 0 | AZ15: 1 | BA15: 1 | BB15: 0 | BC15: 0 | BD15: 1 | BE15: 0 | BF15: 0 | BG15: 0 | BH15: 0 | BI15: 1 | BJ15: 0 | BK15: 0 | BL15: 0 | BM15: 0 | BN15: 0 | BO15: 0 | BP15: =SUM(BF15:BO15) -> 1 | BQ15: 87 | BR15: =SUM(BS15:BZ15) -> 2 | BS15: 0 | BT15: 0 | BU15: 1 | BV15: 1 | BW15: 0 | BX15: 0 | BY15: 0 | BZ15: 0 | CA15: 0 | CB15: 1 | CC15: 0 | CD15: 0 | CE15: 0 | CF15: 0 | CG15: 0 | CH15: 0 | CI15: 0 | CJ15: 0 | CK15: =SUM(CA15:CJ15) -> 1 | CL15: 89 | CM15: 44 | CN15: =SUM(CO15:CV15) -> 8 | CO15: 0 | CP15: 0 | CQ15: 1 | CR15: 1 | CS15: 0 | CT15: 0 | CU15: 3 | CV15: 3 | CW15: 0 | CX15: 0 | CY15: 0 | CZ15: 0 | DA15: 0 | DB15: 0 | DC15: 0 | DD15: 0 | DE15: 0 | DF15: 0 | DG15: =SUM(CW15:DF15) -> 0 | DH15: 80 | DI15: 33 | DJ15: 77 | DK15: 39 | DL15: =SUM(DO15:DV15) -> 6 | DM15: =(DO15+DP15+DQ15+DS15+DT15+DU15) -> 4 | DN15: =DR15+DV15 -> 2 | DO15: 0 | DP15: 0 | DQ15: 4 | DR15: 2 | DS15: 0 | DT15: 0 | DU15: 0 | DV15: 0 | DW15: 0 | DX15: 0 | DY15: 0 | DZ15: 1 | EA15: 0 | EB15: 0 | EC15: 0 | ED15: 1 | EE15: 0 | EF15: 0 | EG15: =SUM(DW15:EF15) -> 2 | EH15: =DW15+DX15+DY15+EA15+EB15+EC15+EE15+EF15 -> 0 | EI15: 87 | EJ15: 42 | EK15: 84 | EL15: 40 | EM15: =SUM(EP15:EW15) -> 5 | EN15: =(EP15+EQ15+ER15+ET15+EU15+EV15) -> 2 | EO15: =ES15+EW15 -> 3 | EP15: 0 | EQ15: 0 | ER15: 2 | ES15: 3 | ET15: 0 | EU15: 0 | EV15: 0 | EW15: 0 | EX15: 0 | EY15: 0 | EZ15: 1 | FA15: 0 | FB15: 0 | FC15: 0 | FD15: 0 | FE15: 0 | FF15: 0 | FG15: 0 | FH15: =SUM(EX15:FG15) -> 1 | FI15: =EX15+EY15+EZ15+FB15+FC15+FD15 -> 1 | FJ15: 83 | FK15: 28 | FL15: 81 | FM15: 27 | FO15: 5 | FP15: =SUM(FS15:FZ15) -> 5 | FQ15: 2 | FR15: 3 | FS15: 0 | FT15: 0 | FU15: 2 | FV15: 3 | FW15: 0 | FX15: 0 | FY15: 0 | FZ15: 0 | GA15: 0 | GB15: 0 | GC15: 0 | GD15: 0 | GE15: 0 | GF15: 0 | GG15: 0 | GH15: 0 | GI15: 0 | GJ15: 0 | GK15: 0 | GL15: 0 | GM15: 84 | GN15: 29 | GO15: 72 | GP15: 25 | GR15: 4 | GS15: 1 | GT15: =GU15+GV15 -> 4 | GU15: =GW15+GX15+GY15+HA15+HB15+HC15 -> 1 | GV15: =GZ15+HD15 -> 3 | GW15: 0 | GX15: 0 | GY15: 1 | GZ15: 3 | HA15: 0 | HB15: 0 | HC15: 0 | HD15: 0 | HE15: 0 | HF15: 0 | HG15: 1 | HH15: 1 | HI15: 0 | HJ15: 0 | HK15: 0 | HL15: 0 | HM15: 0 | HN15: 0 | HT15: =H15 -> 5 | HU15: =P15 -> 7 | HV15: =X15 -> 5 | HW15: =AF15 -> 5 | HX15: =AN15 -> 3 | HY15: =AW15 -> 3 | HZ15: =BR15 -> 2 | IA15: =CN15 -> 8 | IB15: =DL15 -> 6 | IC15: =EM15 -> 5 | ID15: =FP15 -> 5 | IE15: =GT15 -> 4 | JB15: =SUM(I15:L15) -> 5 | JC15: =SUM(Q15:T15) -> 7 | JD15: =SUM(Y15:AB15) -> 5 | JE15: =SUM(AG15:AJ15) -> 5 | JF15: =SUM(AO15:AR15) -> 3 | JG15: =SUM(AX15:BE15) -> 3 | JH15: =SUM(BS15:BZ15) -> 2 | JI15: =SUM(CO15:CV15) -> 8 | JJ15: =SUM(DO15:DV15) -> 6 | JK15: =SUM(EP15:FA15) -> 6 | JL15: =SUM(FS15:FZ15) -> 5 | JM15: =SUM(GW15:HD15) -> 4 | JO15: =H15 -> 5 | JP15: 7 | JQ15: 5 | JR15: 5 | JS15: 3 | JV15: =IA15-JI15 -> 0 | JW15: =IB15-JJ15 -> 0 | JX15: =IC15-JK15 -> -1 | KB15: =JB15-JO15 -> 0 | KC15: =JC15-JP15 -> 0 | KD15: =JD15-JQ15 -> 0 | KE15: =JE15-JR15 -> 0 | KF15: =JF15-JS15 -> 0 | KG15: =JG15-JT15 -> 3 | KH15: =JH15-JU15 -> 2 | KI15: =JI15-JV15 -> 8 | ... KM15: =JM15-JZ15 -> 4
A16: 9 | B16: SEMARANG TENGAH | C16: 3374130 | D16: PONCOL | E16: Bangunharjo | F16: 3 | G16: 99 | H16: 8 | I16: 0 | J16: 1 | K16: 0 | L16: 7 | M16: 4 | N16: 0 | O16: =H16-(M16+N16) -> 4 | P16: 12 | Q16: 1 | R16: 0 | S16: 1 | T16: 10 | U16: 4 | V16: 0 | W16: =P16-(U16+V16) -> 8 | X16: 10 | Y16: 1 | Z16: 0 | AA16: 2 | AB16: 7 | AC16: 1 | AD16: 3 | AE16: =X16-(AC16+AD16) -> 6 | AF16: 10 | AG16: 1 | AH16: 1 | AI16: 1 | AJ16: 7 | AK16: 1 | AL16: 1 | AM16: =AF16-(AK16+AL16) -> 8 | AN16: 7 | AO16: 1 | AP16: 1 | AQ16: 1 | AR16: 4 | AS16: 0 | AT16: 3 | AU16: =AN16-(AS16+AT16) -> 4 | AV16: 69 | AW16: =SUM(AX16:BE16) -> 6 | AX16: 0 | AY16: 1 | AZ16: 1 | BA16: 4 | BB16: 0 | BC16: 0 | BD16: 0 | BE16: 0 | BF16: 1 | BG16: 0 | BH16: 0 | BI16: 0 | BJ16: 0 | BK16: 0 | BL16: 0 | BM16: 0 | BN16: 0 | BO16: 0 | BP16: =SUM(BF16:BO16) -> 1 | BQ16: 66 | BR16: =SUM(BS16:BZ16) -> 6 | BS16: 0 | BT16: 1 | BU16: 1 | BV16: 4 | BW16: 0 | BX16: 0 | BY16: 0 | BZ16: 0 | CA16: 0 | CB16: 0 | CC16: 0 | CD16: 0 | CE16: 0 | CF16: 0 | CG16: 0 | CH16: 0 | CI16: 0 | CJ16: 0 | CK16: =SUM(CA16:CJ16) -> 0 | CL16: 66 | CM16: 33 | CN16: =SUM(CO16:CV16) -> 5 | CO16: 0 | CP16: 0 | CQ16: 1 | CR16: 4 | CS16: 0 | CT16: 0 | CU16: 0 | CV16: 0 | CW16: 0 | CX16: 0 | CY16: 0 | CZ16: 1 | DA16: 0 | DB16: 0 | DC16: 0 | DD16: 0 | DE16: 0 | DF16: 0 | DG16: =SUM(CW16:DF16) -> 1 | DH16: 63 | DI16: 26 | DJ16: 60 | DK16: 24 | DL16: =SUM(DO16:DV16) -> 4 | DM16: =(DO16+DP16+DQ16+DS16+DT16+DU16) -> 1 | DN16: =DR16+DV16 -> 3 | DO16: 0 | DP16: 0 | DQ16: 0 | DR16: 1 | DS16: 1 | DT16: 0 | DU16: 0 | DV16: 2 | DW16: 0 | DX16: 0 | DY16: 1 | DZ16: 3 | EA16: 0 | EB16: 0 | EC16: 0 | ED16: 0 | EE16: 0 | EF16: 0 | EG16: =SUM(DW16:EF16) -> 4 | EH16: =DW16+DX16+DY16+EA16+EB16+EC16+EE16+EF16 -> 1 | EI16: 60 | EJ16: 21 | EK16: 57 | EL16: 18 | EM16: =SUM(EP16:EW16) -> 0 | EN16: =(EP16+EQ16+ER16+ET16+EU16+EV16) -> 0 | EO16: =ES16+EW16 -> 0 | EP16: 0 | EQ16: 0 | ER16: 0 | ES16: 0 | ET16: 0 | EU16: 0 | EV16: 0 | EW16: 0 | EX16: 1 | EY16: 0 | EZ16: 0 | FA16: 2 | FB16: 0 | FC16: 0 | FD16: 0 | FE16: 0 | FF16: 1 | FG16: 0 | FH16: =SUM(EX16:FG16) -> 4 | FI16: =EX16+EY16+EZ16+FB16+FC16+FD16 -> 1 | FJ16: 69 | FK16: 17 | FL16: 69 | FM16: 17 | FO16: 1 | FP16: =SUM(FS16:FZ16) -> 1 | FQ16: 0 | FR16: 1 | FS16: 0 | FT16: 0 | FU16: 0 | FV16: 1 | FW16: 0 | FX16: 0 | FY16: 0 | FZ16: 0 | GA16: 0 | GB16: 0 | GC16: 0 | GD16: 0 | GE16: 0 | GF16: 0 | GG16: 0 | GH16: 0 | GI16: 0 | GJ16: 0 | GK16: 0 | GL16: 0 | GM16: 74 | GN16: 19 | GO16: 73 | GP16: 19 | GR16: 1 | GS16: 0 | GT16: =GU16+GV16 -> 1 | GU16: =GW16+GX16+GY16+HA16+HB16+HC16 -> 0 | GV16: =GZ16+HD16 -> 1 | GW16: 0 | GX16: 0 | GY16: 0 | GZ16: 1 | HA16: 0 | HB16: 0 | HC16: 0 | HD16: 0 | HE16: 0 | HF16: 0 | HG16: 0 | HH16: 0 | HI16: 0 | HJ16: 0 | HK16: 0 | HL16: 0 | HM16: 0 | HN16: 0 | HT16: =H16 -> 8 | HU16: =P16 -> 12 | HV16: =X16 -> 10 | HW16: =AF16 -> 10 | HX16: =AN16 -> 7 | HY16: =AW16 -> 6 | HZ16: =BR16 -> 6 | IA16: =CN16 -> 5 | IB16: =DL16 -> 4 | IC16: =EM16 -> 0 | ID16: =FP16 -> 1 | IE16: =GT16 -> 1 | JB16: =SUM(I16:L16) -> 8 | JC16: =SUM(Q16:T16) -> 12 | JD16: =SUM(Y16:AB16) -> 10 | JE16: =SUM(AG16:AJ16) -> 10 | JF16: =SUM(AO16:AR16) -> 7 | JG16: =SUM(AX16:BE16) -> 6 | JH16: =SUM(BS16:BZ16) -> 6 | JI16: =SUM(CO16:CV16) -> 5 | JJ16: =SUM(DO16:DV16) -> 4 | JK16: =SUM(EP16:FA16) -> 3 | JL16: =SUM(FS16:FZ16) -> 1 | JM16: =SUM(GW16:HD16) -> 1 | JO16: =H16 -> 8 | JP16: 12 | JQ16: 10 | JR16: 10 | JS16: 7 | JV16: =IA16-JI16 -> 0 | JW16: =IB16-JJ16 -> 0 | JX16: =IC16-JK16 -> -3 | KB16: =JB16-JO16 -> 0 | KC16: =JC16-JP16 -> 0 | KD16: =JD16-JQ16 -> 0 | KE16: =JE16-JR16 -> 0 | KF16: =JF16-JS16 -> 0 | KG16: =JG16-JT16 -> 6 | KH16: =JH16-JU16 -> 6 | KI16: =JI16-JV16 -> 5 | ... KM16: =JM16-JZ16 -> 1
A17: 10 | B17: SEMARANG TENGAH | C17: 3374130 | D17: PONCOL | E17: Kauman | F17: 3 | G17: 119 | H17: 8 | I17: 0 | J17: 0 | K17: 0 | L17: 8 | M17: 3 | N17: 0 | O17: =H17-(M17+N17) -> 5 | P17: 8 | Q17: 0 | R17: 0 | S17: 0 | T17: 8 | U17: 5 | V17: 3 | W17: =P17-(U17+V17) -> 0 | X17: 10 | Y17: 1 | Z17: 0 | AA17: 1 | AB17: 8 | AC17: 1 | AD17: 1 | AE17: =X17-(AC17+AD17) -> 8 | AF17: 10 | AG17: 0 | AH17: 1 | AI17: 1 | AJ17: 8 | AK17: 0 | AL17: 0 | AM17: =AF17-(AK17+AL17) -> 10 | AN17: 10 | AO17: 0 | AP17: 1 | AQ17: 0 | AR17: 9 | AS17: 0 | AT17: 0 | AU17: =AN17-(AS17+AT17) -> 10 | AV17: 95 | AW17: =SUM(AX17:BE17) -> 11 | AX17: 0 | AY17: 1 | AZ17: 0 | BA17: 9 | BB17: 0 | BC17: 1 | BD17: 0 | BE17: 0 | BF17: 0 | BG17: 0 | BH17: 0 | BI17: 0 | BJ17: 0 | BK17: 0 | BL17: 0 | BM17: 0 | BN17: 0 | BO17: 0 | BP17: =SUM(BF17:BO17) -> 0 | BQ17: 95 | BR17: =SUM(BS17:BZ17) -> 7 | BS17: 0 | BT17: 1 | BU17: 0 | BV17: 6 | BW17: 0 | BX17: 0 | BY17: 0 | BZ17: 0 | CA17: 0 | CB17: 0 | CC17: 0 | CD17: 3 | CE17: 0 | CF17: 0 | CG17: 0 | CH17: 0 | CI17: 0 | CJ17: 0 | CK17: =SUM(CA17:CJ17) -> 3 | CL17: 87 | CM17: 26 | CN17: =SUM(CO17:CV17) -> 6 | CO17: 0 | CP17: 1 | CQ17: 0 | CR17: 5 | CS17: 0 | CT17: 0 | CU17: 0 | CV17: 0 | CW17: 0 | CX17: 0 | CY17: 0 | CZ17: 1 | DA17: 0 | DB17: 0 | DC17: 0 | DD17: 0 | DE17: 0 | DF17: 0 | DG17: =SUM(CW17:DF17) -> 1 | DH17: 78 | DI17: 24 | DJ17: 76 | DK17: 21 | DL17: =SUM(DO17:DV17) -> 4 | DM17: =(DO17+DP17+DQ17+DS17+DT17+DU17) -> 1 | DN17: =DR17+DV17 -> 3 | DO17: 0 | DP17: 0 | DQ17: 0 | DR17: 3 | DS17: 0 | DT17: 0 | DU17: 1 | DV17: 0 | DW17: 0 | DX17: 1 | DY17: 0 | DZ17: 2 | EA17: 0 | EB17: 0 | EC17: 0 | ED17: 0 | EE17: 0 | EF17: 0 | EG17: =SUM(DW17:EF17) -> 3 | EH17: =DW17+DX17+DY17+EA17+EB17+EC17+EE17+EF17 -> 1 | EI17: 81 | EJ17: 20 | EK17: 78 | EL17: 20 | EM17: =SUM(EP17:EW17) -> 4 | EN17: =(EP17+EQ17+ER17+ET17+EU17+EV17) -> 1 | EO17: =ES17+EW17 -> 3 | EP17: 0 | EQ17: 0 | ER17: 1 | ES17: 3 | ET17: 0 | EU17: 0 | EV17: 0 | EW17: 0 | EX17: 0 | EY17: 0 | EZ17: 0 | FA17: 0 | FB17: 0 | FC17: 0 | FD17: 0 | FE17: 0 | FF17: 0 | FG17: 0 | FH17: =SUM(EX17:FG17) -> 0 | FI17: =EX17+EY17+EZ17+FB17+FC17+FD17 -> 0 | FJ17: 77 | FK17: 12 | FL17: 72 | FM17: 11 | FO17: 3 | FP17: =SUM(FS17:FZ17) -> 3 | FQ17: 1 | FR17: 2 | FS17: 0 | FT17: 0 | FU17: 1 | FV17: 2 | FW17: 0 | FX17: 0 | FY17: 0 | FZ17: 0 | GA17: 0 | GB17: 0 | GC17: 0 | GD17: 1 | GE17: 0 | GF17: 0 | GG17: 0 | GH17: 0 | GI17: 0 | GJ17: 0 | GK17: 1 | GL17: 0 | GM17: 77 | GN17: 11 | GO17: 58 | GP17: 10 | GR17: 4 | GS17: 1 | GT17: =GU17+GV17 -> 4 | GU17: =GW17+GX17+GY17+HA17+HB17+HC17 -> 1 | GV17: =GZ17+HD17 -> 3 | GW17: 0 | GX17: 0 | GY17: 1 | GZ17: 3 | HA17: 0 | HB17: 0 | HC17: 0 | HD17: 0 | HE17: 0 | HF17: 0 | HG17: 0 | HH17: 0 | HI17: 0 | HJ17: 0 | HK17: 0 | HL17: 0 | HM17: 0 | HN17: 0 | HT17: =H17 -> 8 | HU17: =P17 -> 8 | HV17: =X17 -> 10 | HW17: =AF17 -> 10 | HX17: =AN17 -> 10 | HY17: =AW17 -> 11 | HZ17: =BR17 -> 7 | IA17: =CN17 -> 6 | IB17: =DL17 -> 4 | IC17: =EM17 -> 4 | ID17: =FP17 -> 3 | IE17: =GT17 -> 4 | JB17: =SUM(I17:L17) -> 8 | JC17: =SUM(Q17:T17) -> 8 | JD17: =SUM(Y17:AB17) -> 10 | JE17: =SUM(AG17:AJ17) -> 10 | JF17: =SUM(AO17:AR17) -> 10 | JG17: =SUM(AX17:BE17) -> 11 | JH17: =SUM(BS17:BZ17) -> 7 | JI17: =SUM(CO17:CV17) -> 6 | JJ17: =SUM(DO17:DV17) -> 4 | JK17: =SUM(EP17:FA17) -> 4 | JL17: =SUM(FS17:FZ17) -> 3 | JM17: =SUM(GW17:HD17) -> 4 | JO17: =H17 -> 8 | JP17: 8 | JQ17: 10 | JR17: 10 | JS17: 10 | JV17: =IA17-JI17 -> 0 | JW17: =IB17-JJ17 -> 0 | JX17: =IC17-JK17 -> 0 | KB17: =JB17-JO17 -> 0 | KC17: =JC17-JP17 -> 0 | KD17: =JD17-JQ17 -> 0 | KE17: =JE17-JR17 -> 0 | KF17: =JF17-JS17 -> 0 | KG17: =JG17-JT17 -> 11 | KH17: =JH17-JU17 -> 7 | KI17: =JI17-JV17 -> 6 | ... KM17: =JM17-JZ17 -> 4
A18: 11 | B18: SEMARANG TENGAH | C18: 3374130 | D18: PONCOL | E18: Purwodinatan | F18: 6 | G18: 136 | H18: 7 | I18: 0 | J18: 0 | K18: 1 | L18: 6 | M18: 6 | N18: 0 | O18: =H18-(M18+N18) -> 1 | P18: 17 | Q18: 0 | R18: 0 | S18: 6 | T18: 11 | U18: 5 | V18: 3 | W18: =P18-(U18+V18) -> 9 | X18: 17 | Y18: 2 | Z18: 0 | AA18: 4 | AB18: 11 | AC18: 2 | AD18: 0 | AE18: =X18-(AC18+AD18) -> 15 | AF18: 18 | AG18: 2 | AH18: 0 | AI18: 3 | AJ18: 13 | AK18: 1 | AL18: 0 | AM18: =AF18-(AK18+AL18) -> 17 | AN18: 14 | AO18: 2 | AP18: 0 | AQ18: 3 | AR18: 9 | AS18: 0 | AT18: 4 | AU18: =AN18-(AS18+AT18) -> 10 | AV18: 197 | AW18: =SUM(AX18:BE18) -> 13 | AX18: 2 | AY18: 0 | AZ18: 3 | BA18: 8 | BB18: 0 | BC18: 0 | BD18: 0 | BE18: 0 | BF18: 0 | BG18: 0 | BH18: 0 | BI18: 1 | BJ18: 0 | BK18: 0 | BL18: 0 | BM18: 0 | BN18: 0 | BO18: 0 | BP18: =SUM(BF18:BO18) -> 1 | BQ18: 189 | BR18: =SUM(BS18:BZ18) -> 11 | BS18: 1 | BT18: 1 | BU18: 1 | BV18: 6 | BW18: 1 | BX18: 0 | BY18: 1 | BZ18: 0 | CA18: 0 | CB18: 0 | CC18: 1 | CD18: 2 | CE18: 0 | CF18: 0 | CG18: 0 | CH18: 0 | CI18: 1 | CJ18: 0 | CK18: =SUM(CA18:CJ18) -> 4 | CL18: 178 | CM18: 61 | CN18: =SUM(CO18:CV18) -> 10 | CO18: 1 | CP18: 2 | CQ18: 1 | CR18: 5 | CS18: 0 | CT18: 0 | CU18: 1 | CV18: 0 | CW18: 0 | CX18: 0 | CY18: 1 | CZ18: 1 | DA18: 0 | DB18: 0 | DC18: 0 | DD18: 0 | DE18: 0 | DF18: 0 | DG18: =SUM(CW18:DF18) -> 2 | DH18: 179 | DI18: 80 | DJ18: 176 | DK18: 59 | DL18: =SUM(DO18:DV18) -> 9 | DM18: =(DO18+DP18+DQ18+DS18+DT18+DU18) -> 4 | DN18: =DR18+DV18 -> 5 | DO18: 0 | DP18: 0 | DQ18: 0 | DR18: 3 | DS18: 0 | DT18: 1 | DU18: 3 | DV18: 2 | DW18: 1 | DX18: 2 | DY18: 2 | DZ18: 2 | EA18: 0 | EB18: 0 | EC18: 0 | ED18: 0 | EE18: 0 | EF18: 0 | EG18: =SUM(DW18:EF18) -> 7 | EH18: =DW18+DX18+DY18+EA18+EB18+EC18+EE18+EF18 -> 5 | EI18: 188 | EJ18: 67 | EK18: 182 | EL18: 63 | EM18: =SUM(EP18:EW18) -> 7 | EN18: =(EP18+EQ18+ER18+ET18+EU18+EV18) -> 2 | EO18: =ES18+EW18 -> 5 | EP18: 0 | EQ18: 0 | ER18: 2 | ES18: 4 | ET18: 0 | EU18: 0 | EV18: 0 | EW18: 1 | EX18: 0 | EY18: 0 | EZ18: 1 | FA18: 2 | FB18: 0 | FC18: 0 | FD18: 0 | FE18: 0 | FF18: 0 | FG18: 0 | FH18: =SUM(EX18:FG18) -> 3 | FI18: =EX18+EY18+EZ18+FB18+FC18+FD18 -> 1 | FJ18: 206 | FK18: 51 | FL18: 194 | FM18: 50 | FO18: 5 | FP18: =SUM(FS18:FZ18) -> 5 | FQ18: 2 | FR18: 3 | FS18: 0 | FT18: 0 | FU18: 1 | FV18: 3 | FW18: 0 | FX18: 0 | FY18: 1 | FZ18: 0 | GA18: 0 | GB18: 1 | GC18: 0 | GD18: 2 | GE18: 0 | GF18: 0 | GG18: 0 | GH18: 0 | GI18: 0 | GJ18: 0 | GK18: 3 | GL18: 1 | GM18: 219 | GN18: 58 | GO18: 219 | GP18: 58 | GR18: 8 | GS18: 2 | GT18: =GU18+GV18 -> 8 | GU18: =GW18+GX18+GY18+HA18+HB18+HC18 -> 2 | GV18: =GZ18+HD18 -> 6 | GW18: 0 | GX18: 0 | GY18: 1 | GZ18: 3 | HA18: 0 | HB18: 0 | HC18: 1 | HD18: 3 | HE18: 0 | HF18: 0 | HG18: 0 | HH18: 0 | HI18: 0 | HJ18: 0 | HK18: 0 | HL18: 0 | HM18: 1 | HN18: 0 | HT18: =H18 -> 7 | HU18: =P18 -> 17 | HV18: =X18 -> 17 | HW18: =AF18 -> 18 | HX18: =AN18 -> 14 | HY18: =AW18 -> 13 | HZ18: =BR18 -> 11 | IA18: =CN18 -> 10 | IB18: =DL18 -> 9 | IC18: =EM18 -> 7 | ID18: =FP18 -> 5 | IE18: =GT18 -> 8 | JB18: =SUM(I18:L18) -> 7 | JC18: =SUM(Q18:T18) -> 17 | JD18: =SUM(Y18:AB18) -> 17 | JE18: =SUM(AG18:AJ18) -> 18 | JF18: =SUM(AO18:AR18) -> 14 | JG18: =SUM(AX18:BE18) -> 13 | JH18: =SUM(BS18:BZ18) -> 11 | JI18: =SUM(CO18:CV18) -> 10 | JJ18: =SUM(DO18:DV18) -> 9 | JK18: =SUM(EP18:FA18) -> 10 | JL18: =SUM(FS18:FZ18) -> 5 | JM18: =SUM(GW18:HD18) -> 8 | JO18: =H18 -> 7 | JP18: 17 | JQ18: 17 | JR18: 18 | JS18: 14 | JV18: =IA18-JI18 -> 0 | JW18: =IB18-JJ18 -> 0 | JX18: =IC18-JK18 -> -3 | KB18: =JB18-JO18 -> 0 | KC18: =JC18-JP18 -> 0 | KD18: =JD18-JQ18 -> 0 | KE18: =JE18-JR18 -> 0 | KF18: =JF18-JS18 -> 0 | KG18: =JG18-JT18 -> 13 | KH18: =JH18-JU18 -> 11 | KI18: =JI18-JV18 -> 10 | ... KM18: =JM18-JZ18 -> 8
A19: 12 | B19: SEMARANG TENGAH | C19: 3374130 | D19: MIROTO | E19: Karangkidul | F19: 4 | G19: 179 | H19: 3 | L19: 3 | M19: 0 | N19: 0 | O19: =H19-(M19+N19) -> 3 | P19: 1 | T19: 1 | U19: 0 | V19: 0 | W19: =P19-(U19+V19) -> 1 | X19: 3 | AB19: 3 | AC19: 0 | AD19: 0 | AE19: =X19-(AC19+AD19) -> 3 | AF19: 3 | AJ19: 3 | AK19: 0 | AL19: 0 | AM19: =AF19-(AK19+AL19) -> 3 | AN19: 3 | AR19: 3 | AS19: 0 | AT19: 0 | AU19: =AN19-(AS19+AT19) -> 3 | AV19: 188 | AW19: =SUM(AX19:BE19) -> 3 | AX19: 0 | AY19: 0 | AZ19: 0 | BA19: 3 | BB19: 0 | BC19: 0 | BD19: 0 | BE19: 0 | BF19: 0 | BG19: 0 | BH19: 0 | BI19: 1 | BJ19: 0 | BK19: 0 | BL19: 0 | BM19: 0 | BN19: 0 | BO19: 0 | BP19: =SUM(BF19:BO19) -> 1 | BQ19: 185 | BR19: =SUM(BS19:BZ19) -> 3 | BS19: 0 | BT19: 0 | BU19: 0 | BV19: 3 | BW19: 0 | BX19: 0 | BY19: 0 | BZ19: 0 | CA19: 0 | CB19: 0 | CC19: 0 | CD19: 0 | CE19: 0 | CF19: 0 | CG19: 0 | CH19: 0 | CI19: 0 | CJ19: 0 | CK19: =SUM(CA19:CJ19) -> 0 | CL19: 177 | CM19: 66 | CN19: =SUM(CO19:CV19) -> 7 | CO19: 0 | CP19: 0 | CQ19: 0 | CR19: 3 | CS19: 0 | CT19: 1 | CU19: 1 | CV19: 2 | CW19: 0 | CX19: 0 | CY19: 0 | CZ19: 1 | DA19: 0 | DB19: 0 | DC19: 0 | DD19: 0 | DE19: 0 | DF19: 0 | DG19: =SUM(CW19:DF19) -> 1 | DH19: 130 | DI19: 42 | DJ19: 130 | DK19: 42 | DL19: =SUM(DO19:DV19) -> 3 | DM19: =(DO19+DP19+DQ19+DS19+DT19+DU19) -> 0 | DN19: =DR19+DV19 -> 3 | DO19: 0 | DP19: 0 | DQ19: 0 | DR19: 3 | DS19: 0 | DT19: 0 | DU19: 0 | DV19: 0 | DW19: 0 | DX19: 1 | DY19: 1 | DZ19: 2 | EA19: 0 | EB19: 0 | EC19: 0 | ED19: 0 | EE19: 0 | EF19: 0 | EG19: =SUM(DW19:EF19) -> 4 | EH19: =DW19+DX19+DY19+EA19+EB19+EC19+EE19+EF19 -> 2 | EI19: 129 | EJ19: 37 | EK19: 129 | EL19: 37 | EM19: =SUM(EP19:EW19) -> 3 | EN19: =(EP19+EQ19+ER19+ET19+EU19+EV19) -> 0 | EO19: =ES19+EW19 -> 3 | EP19: 0 | EQ19: 0 | ER19: 0 | ES19: 3 | ET19: 0 | EU19: 0 | EV19: 0 | EW19: 0 | EX19: 0 | EY19: 0 | EZ19: 0 | FA19: 0 | FB19: 0 | FC19: 0 | FD19: 0 | FE19: 0 | FF19: 0 | FG19: 0 | FH19: =SUM(EX19:FG19) -> 0 | FI19: =EX19+EY19+EZ19+FB19+FC19+FD19 -> 0 | FJ19: 124 | FK19: 33 | FL19: 124 | FM19: 33 | FO19: 3 | FP19: =SUM(FS19:FZ19) -> 3 | FQ19: 0 | FR19: 3 | FS19: 0 | FT19: 0 | FU19: 0 | FV19: 3 | FW19: 0 | FX19: 0 | FY19: 0 | FZ19: 0 | GA19: 0 | GB19: 0 | GC19: 0 | GD19: 0 | GE19: 0 | GF19: 0 | GG19: 0 | GH19: 0 | GI19: 0 | GJ19: 0 | GK19: 0 | GL19: 0 | GM19: 122 | GN19: 34 | GO19: 122 | GP19: 34 | GR19: 3 | GS19: 0 | GT19: =GU19+GV19 -> 3 | GU19: =GW19+GX19+GY19+HA19+HB19+HC19 -> 0 | GV19: =GZ19+HD19 -> 3 | GW19: 0 | GX19: 0 | GY19: 0 | GZ19: 3 | HA19: 0 | HB19: 0 | HC19: 0 | HD19: 0 | HE19: 0 | HF19: 0 | HG19: 0 | HH19: 0 | HI19: 0 | HJ19: 0 | HK19: 0 | HL19: 0 | HM19: 0 | HN19: 0 | HO19: 0 | HP19: 0 | HT19: =H19 -> 3 | HU19: =P19 -> 1 | HV19: =X19 -> 3 | HW19: =AF19 -> 3 | HX19: =AN19 -> 3 | HY19: =AW19 -> 3 | HZ19: =BR19 -> 3 | IA19: =CN19 -> 7 | IB19: =DL19 -> 3 | IC19: =EM19 -> 3 | ID19: =FP19 -> 3 | IE19: =GT19 -> 3 | JB19: =SUM(I19:L19) -> 3 | JC19: =SUM(Q19:T19) -> 1 | JD19: =SUM(Y19:AB19) -> 3 | JE19: =SUM(AG19:AJ19) -> 3 | JF19: =SUM(AO19:AR19) -> 3 | JG19: =SUM(AX19:BE19) -> 3 | JH19: =SUM(BS19:BZ19) -> 3 | JI19: =SUM(CO19:CV19) -> 7 | JJ19: =SUM(DO19:DV19) -> 3 | JK19: =SUM(EP19:FA19) -> 3 | JL19: =SUM(FS19:FZ19) -> 3 | JM19: =SUM(GW19:HD19) -> 3 | JO19: =H19 -> 3 | JP19: 1 | JQ19: 3 | JR19: 3 | JS19: 3 | JV19: =IA19-JI19 -> 0 | JW19: =IB19-JJ19 -> 0 | JX19: =IC19-JK19 -> 0 | KB19: =JB19-JO19 -> 0 | KC19: =JC19-JP19 -> 0 | KD19: =JD19-JQ19 -> 0 | KE19: =JE19-JR19 -> 0 | KF19: =JF19-JS19 -> 0 | KG19: =JG19-JT19 -> 3 | KH19: =JH19-JU19 -> 3 | KI19: =JI19-JV19 -> 7 | ... KM19: =JM19-JZ19 -> 3
A20: 13 | B20: SEMARANG TENGAH | C20: 3374130 | D20: MIROTO | E20: Pekunden | F20: 3 | G20: 136 | H20: 0 | M20: 0 | N20: 0 | O20: =H20-(M20+N20) -> 0 | P20: 5 | S20: 5 | U20: 0 | V20: 5 | W20: =P20-(U20+V20) -> 0 | X20: 1 | AA20: 1 | AC20: 0 | AD20: 0 | AE20: =X20-(AC20+AD20) -> 1 | AF20: 0 | AG20: 0 | AH20: 0 | AI20: 0 | AJ20: 0 | AK20: 0 | AL20: 0 | AM20: =AF20-(AK20+AL20) -> 0 | AN20: 1 | AQ20: 1 | AS20: 0 | AT20: 0 | AU20: =AN20-(AS20+AT20) -> 1 | AV20: 134 | AW20: =SUM(AX20:BE20) -> 1 | AX20: 0 | AY20: 0 | AZ20: 1 | BA20: 0 | BB20: 0 | BC20: 0 | BD20: 0 | BE20: 0 | BF20: 0 | BG20: 0 | BH20: 0 | BI20: 0 | BJ20: 0 | BK20: 0 | BL20: 0 | BM20: 0 | BN20: 0 | BO20: 0 | BP20: =SUM(BF20:BO20) -> 0 | BQ20: 132 | BR20: =SUM(BS20:BZ20) -> 0 | BS20: 0 | BT20: 0 | BU20: 0 | BV20: 0 | BW20: 0 | BX20: 0 | BY20: 0 | BZ20: 0 | CA20: 0 | CB20: 0 | CC20: 0 | CD20: 1 | CE20: 0 | CF20: 0 | CG20: 0 | CH20: 0 | CI20: 0 | CJ20: 0 | CK20: =SUM(CA20:CJ20) -> 1 | CL20: 132 | CM20: 35 | CN20: =SUM(CO20:CV20) -> 0 | CO20: 0 | CP20: 0 | CQ20: 0 | CR20: 0 | CS20: 0 | CT20: 0 | CU20: 0 | CV20: 0 | CW20: 0 | CX20: 0 | CY20: 0 | CZ20: 0 | DA20: 0 | DB20: 0 | DC20: 0 | DD20: 0 | DE20: 0 | DF20: 0 | DG20: =SUM(CW20:DF20) -> 0 | DH20: 74 | DI20: 24 | DJ20: 74 | DK20: 24 | DL20: =SUM(DO20:DV20) -> 1 | DM20: =(DO20+DP20+DQ20+DS20+DT20+DU20) -> 0 | DN20: =DR20+DV20 -> 1 | DO20: 0 | DP20: 0 | DQ20: 0 | DR20: 1 | DS20: 0 | DT20: 0 | DU20: 0 | DV20: 0 | DW20: 0 | DX20: 0 | DY20: 0 | DZ20: 0 | EA20: 0 | EB20: 0 | EC20: 0 | ED20: 0 | EE20: 0 | EF20: 0 | EG20: =SUM(DW20:EF20) -> 0 | EH20: =DW20+DX20+DY20+EA20+EB20+EC20+EE20+EF20 -> 0 | EI20: 76 | EJ20: 25 | EK20: 76 | EL20: 25 | EM20: =SUM(EP20:EW20) -> 1 | EN20: =(EP20+EQ20+ER20+ET20+EU20+EV20) -> 0 | EO20: =ES20+EW20 -> 1 | EP20: 0 | EQ20: 0 | ER20: 0 | ES20: 1 | ET20: 0 | EU20: 0 | EV20: 0 | EW20: 0 | EX20: 0 | EY20: 0 | EZ20: 0 | FA20: 0 | FB20: 0 | FC20: 0 | FD20: 0 | FE20: 0 | FF20: 0 | FG20: 0 | FH20: =SUM(EX20:FG20) -> 0 | FI20: =EX20+EY20+EZ20+FB20+FC20+FD20 -> 0 | FJ20: 76 | FK20: 23 | FL20: 76 | FM20: 23 | FO20: 1 | FP20: =SUM(FS20:FZ20) -> 1 | FQ20: 0 | FR20: 1 | FS20: 0 | FT20: 0 | FU20: 0 | FV20: 1 | FW20: 0 | FX20: 0 | FY20: 0 | FZ20: 0 | GA20: 0 | GB20: 0 | GC20: 0 | GD20: 0 | GE20: 0 | GF20: 0 | GG20: 0 | GH20: 0 | GI20: 0 | GJ20: 0 | GK20: 0 | GL20: 0 | GM20: 77 | GN20: 22 | GO20: 77 | GP20: 22 | GR20: 2 | GS20: 1 | GT20: =GU20+GV20 -> 2 | GU20: =GW20+GX20+GY20+HA20+HB20+HC20 -> 1 | GV20: =GZ20+HD20 -> 1 | GW20: 0 | GX20: 0 | GY20: 0 | GZ20: 1 | HA20: 1 | HB20: 0 | HC20: 0 | HD20: 0 | HE20: 0 | HF20: 0 | HG20: 0 | HH20: 0 | HI20: 0 | HJ20: 0 | HK20: 0 | HL20: 0 | HM20: 0 | HN20: 0 | HO20: 0 | HP20: 0 | HT20: =H20 -> 0 | HU20: =P20 -> 5 | HV20: =X20 -> 1 | HW20: =AF20 -> 0 | HX20: =AN20 -> 1 | HY20: =AW20 -> 1 | HZ20: =BR20 -> 0 | IA20: =CN20 -> 0 | IB20: =DL20 -> 1 | IC20: =EM20 -> 1 | ID20: =FP20 -> 1 | IE20: =GT20 -> 2 | JB20: =SUM(I20:L20) -> 0 | JC20: =SUM(Q20:T20) -> 5 | JD20: =SUM(Y20:AB20) -> 1 | JE20: =SUM(AG20:AJ20) -> 0 | JF20: =SUM(AO20:AR20) -> 1 | JG20: =SUM(AX20:BE20) -> 1 | JH20: =SUM(BS20:BZ20) -> 0 | JI20: =SUM(CO20:CV20) -> 0 | JJ20: =SUM(DO20:DV20) -> 1 | JK20: =SUM(EP20:FA20) -> 1 | JL20: =SUM(FS20:FZ20) -> 1 | JM20: =SUM(GW20:HD20) -> 2 | JO20: =H20 -> 0 | JP20: 5 | JQ20: 1 | JR20: 0 | JS20: 1 | JV20: =IA20-JI20 -> 0 | JW20: =IB20-JJ20 -> 0 | JX20: =IC20-JK20 -> 0 | KB20: =JB20-JO20 -> 0 | KC20: =JC20-JP20 -> 0 | KD20: =JD20-JQ20 -> 0 | KE20: =JE20-JR20 -> 0 | KF20: =JF20-JS20 -> 0 | KG20: =JG20-JT20 -> 1 | KH20: =JH20-JU20 -> 0 | KI20: =JI20-JV20 -> 0 | ... KM20: =JM20-JZ20 -> 2
A21: 14 | B21: SEMARANG TENGAH | C21: 3374130 | D21: PONCOL | E21: Pendrikan Kidul | F21: 5 | G21: 106 | H21: 7 | I21: 0 | J21: 0 | K21: 0 | L21: 7 | M21: 0 | N21: 0 | O21: =H21-(M21+N21) -> 7 | P21: 9 | Q21: 1 | R21: 0 | S21: 2 | T21: 6 | U21: 1 | V21: 1 | W21: =P21-(U21+V21) -> 7 | X21: 8 | Y21: 1 | Z21: 1 | AA21: 0 | AB21: 6 | AC21: 2 | AD21: 1 | AE21: =X21-(AC21+AD21) -> 5 | AF21: 6 | AG21: 0 | AH21: 1 | AI21: 0 | AJ21: 5 | AK21: 0 | AL21: 2 | AM21: =AF21-(AK21+AL21) -> 4 | AN21: 6 | AO21: 0 | AP21: 1 | AQ21: 0 | AR21: 5 | AS21: 0 | AT21: 0 | AU21: =AN21-(AS21+AT21) -> 6 | AV21: 90 | AW21: =SUM(AX21:BE21) -> 6 | AX21: 0 | AY21: 1 | AZ21: 0 | BA21: 5 | BB21: 0 | BC21: 0 | BD21: 0 | BE21: 0 | BF21: 0 | BG21: 0 | BH21: 0 | BI21: 0 | BJ21: 0 | BK21: 0 | BL21: 0 | BM21: 0 | BN21: 0 | BO21: 0 | BP21: =SUM(BF21:BO21) -> 0 | BQ21: 91 | BR21: =SUM(BS21:BZ21) -> 6 | BS21: 0 | BT21: 1 | BU21: 0 | BV21: 4 | BW21: 1 | BX21: 0 | BY21: 0 | BZ21: 0 | CA21: 0 | CB21: 0 | CC21: 0 | CD21: 0 | CE21: 0 | CF21: 0 | CG21: 0 | CH21: 0 | CI21: 1 | CJ21: 0 | CK21: =SUM(CA21:CJ21) -> 1 | CL21: 101 | CM21: 57 | CN21: =SUM(CO21:CV21) -> 15 | CO21: 1 | CP21: 1 | CQ21: 0 | CR21: 4 | CS21: 0 | CT21: 2 | CU21: 0 | CV21: 7 | CW21: 0 | CX21: 0 | CY21: 0 | CZ21: 0 | DA21: 0 | DB21: 0 | DC21: 0 | DD21: 0 | DE21: 0 | DF21: 0 | DG21: =SUM(CW21:DF21) -> 0 | DH21: 94 | DI21: 42 | DJ21: 92 | DK21: 45 | DL21: =SUM(DO21:DV21) -> 8 | DM21: =(DO21+DP21+DQ21+DS21+DT21+DU21) -> 1 | DN21: =DR21+DV21 -> 7 | DO21: 0 | DP21: 0 | DQ21: 0 | DR21: 7 | DS21: 0 | DT21: 0 | DU21: 1 | DV21: 0 | DW21: 1 | DX21: 3 | DY21: 0 | DZ21: 4 | EA21: 0 | EB21: 0 | EC21: 0 | ED21: 0 | EE21: 0 | EF21: 0 | EG21: =SUM(DW21:EF21) -> 8 | EH21: =DW21+DX21+DY21+EA21+EB21+EC21+EE21+EF21 -> 4 | EI21: 97 | EJ21: 47 | EK21: 95 | EL21: 43 | EM21: =SUM(EP21:EW21) -> 7 | EN21: =(EP21+EQ21+ER21+ET21+EU21+EV21) -> 2 | EO21: =ES21+EW21 -> 5 | EP21: 0 | EQ21: 0 | ER21: 1 | ES21: 5 | ET21: 0 | EU21: 0 | EV21: 1 | EW21: 0 | EX21: 0 | EY21: 0 | EZ21: 0 | FA21: 2 | FB21: 0 | FC21: 0 | FD21: 0 | FE21: 0 | FF21: 0 | FG21: 0 | FH21: =SUM(EX21:FG21) -> 2 | FI21: =EX21+EY21+EZ21+FB21+FC21+FD21 -> 0 | FJ21: 97 | FK21: 32 | FL21: 97 | FM21: 32 | FO21: 8 | FP21: =SUM(FS21:FZ21) -> 8 | FQ21: 2 | FR21: 6 | FS21: 0 | FT21: 0 | FU21: 2 | FV21: 5 | FW21: 0 | FX21: 0 | FY21: 0 | FZ21: 1 | GA21: 0 | GB21: 0 | GC21: 0 | GD21: 0 | GE21: 0 | GF21: 0 | GG21: 0 | GH21: 0 | GI21: 0 | GJ21: 0 | GK21: 0 | GL21: 0 | GM21: 95 | GN21: 28 | GO21: 95 | GP21: 28 | GR21: 8 | GS21: 2 | GT21: =GU21+GV21 -> 8 | GU21: =GW21+GX21+GY21+HA21+HB21+HC21 -> 2 | GV21: =GZ21+HD21 -> 6 | GW21: 0 | GX21: 0 | GY21: 1 | GZ21: 6 | HA21: 0 | HB21: 0 | HC21: 1 | HD21: 0 | HE21: 0 | HF21: 0 | HG21: 0 | HH21: 1 | HI21: 0 | HJ21: 0 | HK21: 0 | HL21: 0 | HM21: 0 | HN21: 0 | HT21: =H21 -> 7 | HU21: =P21 -> 9 | HV21: =X21 -> 8 | HW21: =AF21 -> 6 | HX21: =AN21 -> 6 | HY21: =AW21 -> 6 | HZ21: =BR21 -> 6 | IA21: =CN21 -> 15 | IB21: =DL21 -> 8 | IC21: =EM21 -> 7 | ID21: =FP21 -> 8 | IE21: =GT21 -> 8 | JB21: =SUM(I21:L21) -> 7 | JC21: =SUM(Q21:T21) -> 9 | JD21: =SUM(Y21:AB21) -> 8 | JE21: =SUM(AG21:AJ21) -> 6 | JF21: =SUM(AO21:AR21) -> 6 | JG21: =SUM(AX21:BE21) -> 6 | JH21: =SUM(BS21:BZ21) -> 6 | JI21: =SUM(CO21:CV21) -> 15 | JJ21: =SUM(DO21:DV21) -> 8 | JK21: =SUM(EP21:FA21) -> 9 | JL21: =SUM(FS21:FZ21) -> 8 | JM21: =SUM(GW21:HD21) -> 8 | JO21: =H21 -> 7 | JP21: 9 | JQ21: 8 | JR21: 6 | JS21: 6 | JV21: =IA21-JI21 -> 0 | JW21: =IB21-JJ21 -> 0 | JX21: =IC21-JK21 -> -2 | KB21: =JB21-JO21 -> 0 | KC21: =JC21-JP21 -> 0 | KD21: =JD21-JQ21 -> 0 | KE21: =JE21-JR21 -> 0 | KF21: =JF21-JS21 -> 0 | KG21: =JG21-JT21 -> 6 | KH21: =JH21-JU21 -> 6 | KI21: =JI21-JV21 -> 15 | ... KM21: =JM21-JZ21 -> 8
